Workbook

Sheet FM_Dashboard
A1: AKA | B1: AGA KHAN ACADEMY | FACILITY MANAGEMENT MIS DASHBOARD
A2: HYDERABAD · FM | B2: ="Calendar 2026 • live MIS data Jan-26 to "&MIS_Calc!$B$6&" • Water · Energy · Solar · HVAC · Treatment · Service desk · Manpower • "&TEXT(MIS_Calc!$B$15,"#,##0")&" occupants • "&TEXT(MIS_Calc!$B$7,"#,##0")&" m² built-up" -> Calendar 2026 • live MIS data Jan-26 to Aug-26 • Water · Energy · Solar · HVAC · Treatment · Service desk · Manpower • 1,354 occupants • 52,652 m² built-up
B4: MONTH | H4: FACILITY | P4: ="Showing: "&MIS_Calc!$B$3&" • Facility drill: "&MIS_Calc!$B$4&" • Data completeness "&IF(MIS_Calc!$F$80="","n/a",TEXT(MIS_Calc!$F$80,"0%")) -> Showing: Aug-26 • Facility drill: All Facilities • Data completeness 88%
A5: ▶ FM Dashboard | B5: 📅 Select ▸ | D5: Aug-26 | H5: 🏢 Drill ▸ | J5: All Facilities | P5: Pick a month (or 2026 YTD) from the yellow drop-down; the facility drop-down drives the drill-down charts & highlights the scorecard. 'vs 2025' compares the monthly average with the Avg-2025 row of each source sheet.
A7: Per-Capita Pyramid | B7: 💧 WATER CONSUMED (kL) | F7: 🚰 LPCD (L / person / day) | J7: ⛲ BOREWELL DRAW (kL) | N7: ⚡ HT GRID ENERGY (kWh) | R7: ₹ ENERGY BILL (₹ Lakh) | V7: 🏢 EPI (kWh / m² / month)
B8: =IF(MIS_Calc!$E$44="","NO DATA",MIS_Calc!$E$44) -> 14026 | F8: =IF(MIS_Calc!$F$46="","NO DATA",MIS_Calc!$F$46) -> 334.15924 | J8: =IF(MIS_Calc!$E$47="","NO DATA",MIS_Calc!$E$47) -> 11995 | N8: =IF(MIS_Calc!$E$51="","NO DATA",MIS_Calc!$E$51) -> 146382 | R8: =IF(MIS_Calc!$E$54="","NO DATA",MIS_Calc!$E$54/100000) -> 18.29571 | V8: =IF(MIS_Calc!$F$58="","NO DATA",MIS_Calc!$F$58) -> 2.7801652
A9: Monthly KPI | B9: =IF($B$8="NO DATA","no data for this month","Avg/month "&TEXT(MIS_Calc!$F$44,"#,##0")&" • "&IF(MIS_Calc!$J$44="","vs Avg-2025 –","vs Avg-2025 "&TEXT(MIS_Calc!$J$44,"+0%;-0%;0%"))) -> Avg/month 14,026 • vs Avg-2025 -86% | F9: =IF(MIS_Calc!$F$46="","","Benchmark "&MIS_Calc!$B$8&" • "&IF(MIS_Calc!$F$46<=MIS_Calc!$B$8,"✔ within","▲ "&TEXT(MIS_Calc!$F$46/MIS_Calc!$B$8,"0.0")&"× benchmark")) -> Benchmark 135 • ▲ 2.5× benchmark | J9: =IF($J$8="NO DATA","no data for this month","STP recycled "&IF(MIS_Calc!$E$48="","–",TEXT(MIS_Calc!$E$48,"#,##0"))&" kL ("&TEXT(MIS_Calc!$F$90,"0%")&" of inlet)") -> STP recycled 2,683 kL (18% of inlet) | N9: =IF($N$8="NO DATA","no data for this month","Avg/month "&TEXT(MIS_Calc!$F$51,"#,##0")&" • "&IF(MIS_Calc!$J$51="","vs Avg-2025 –","vs Avg-2025 "&TEXT(MIS_Calc!$J$51,"+0%;-0%;0%"))) -> Avg/month 1,46,382 • vs Avg-2025 +10% | R9: =IF($R$8="NO DATA","no data for this month","₹"&TEXT(MIS_Calc!$F$55,"0.00")&"/kVAh • "&IF(MIS_Calc!$J$54="","bill vs Avg-2025 –","bill vs Avg-2025 "&TEXT(MIS_Calc!$J$54,"+0%;-0%;0%"))) -> ₹11.70/kVAh • bill vs Avg-2025 +5% | V9: =IF(MIS_Calc!$F$58="","","Benchmark ≤ "&MIS_Calc!$B$9&" • "&IF(MIS_Calc!$F$58<=MIS_Calc!$B$9,"✔ on target","▲ above")) -> Benchmark ≤ 8 • ✔ on target
A11: Complaints | B11: 🔌 POWER FACTOR | F11: ☀ SOLAR GENERATION (kWh) | J11: ❄ HVAC ENERGY (kWh) | N11: 🎫 COMPLAINTS RECEIVED | R11: 👷 TECH DEPLOYMENT | V11: 🚿 WTP TREATED WATER (kL)
B12: =IF(MIS_Calc!$F$53="","NO DATA",MIS_Calc!$F$53) -> 0.93618573 | F12: =IF(MIS_Calc!$E$59="","NO DATA",MIS_Calc!$E$59) -> 115911 | J12: =IF(MIS_Calc!$E$65="","NO DATA",MIS_Calc!$E$65) -> 21957.88 | N12: =IF(MIS_Calc!$E$40="","NO DATA",MIS_Calc!$E$40) -> 216 | R12: =IF(MIS_Calc!$F$77="","NO DATA",MIS_Calc!$F$77) -> 0.8484375 | V12: =IF(MIS_Calc!$E$49="","NO DATA",MIS_Calc!$E$49) -> 10986
A13: Water - Bldg | B13: =IF(MIS_Calc!$F$53="","","Target "&MIS_Calc!$B$10&" • "&IF(MIS_Calc!$F$53>=MIS_Calc!$B$10,"✔ OK","▲ below target")&" • MD "&TEXT(MIS_Calc!$F$85,"0%")&" of sanctioned") -> Target 0.95 • ▲ below target • MD 37% of sanctioned | F13: =IF($F$12="NO DATA","no data for this month","Savings ₹"&TEXT(N(MIS_Calc!$E$61)/100000,"#,##0.0")&" L • "&IF(MIS_Calc!$J$59="","vs Avg-2025 –","vs Avg-2025 "&TEXT(MIS_Calc!$J$59,"+0%;-0%;0%"))) -> Savings ₹13.7 L • vs Avg-2025 +35% | J13: =IF($J$12="NO DATA","no data for this month",IF(MIS_Calc!$J$65="","vs Avg-2025 –","vs Avg-2025 "&TEXT(MIS_Calc!$J$65,"+0%;-0%;0%"))) -> vs Avg-2025 +5% | N13: =IF(MIS_Calc!$E$40="","Not logged for this month • latest entry "&IFERROR(LOOKUP(2,1/(MIS_Calc!$C$21:$C$32<>""),MIS_Calc!$A$21:$A$32),"–"),"Closure "&TEXT(MIS_Calc!$F$98,"0%")&" • Pending "&IF(MIS_Calc!$E$42="","–",MIS_Calc!$E$42)&" • "&MIS_Calc!$G$40&" months logged") -> Closure 68% • Pending – • 5 months logged | R13: =IF($R$12="NO DATA","no data for this month","Target "&TEXT(MIS_Calc!$B$11,"0%")&" • Present "&TEXT(MIS_Calc!$E$75,"#,##0")&" / "&TEXT(MIS_Calc!$E$76,"#,##0")&" man-days") -> Target 90% • Present 543 / 640 man-days | V13: =IF($V$12="NO DATA","no data for this month","Avg/month "&TEXT(MIS_Calc!$F$49,"#,##0")&" • "&IF(MIS_Calc!$J$49="","vs Avg-2025 –","vs Avg-2025 "&TEXT(MIS_Calc!$J$49,"+0%;-0%;0%"))&" • Drip "&IF(MIS_Calc!$E$50="","–",TEXT(MIS_Calc!$E$50,"#,##0"))&" kL") -> Avg/month 10,986 • vs Avg-2025 +2% • Drip 2,501 kL
A15: LPCD
A17: Water Quality
A19: Power
A21: EPI
A23: Power - Bldg
A25: Solar
A27: HVAC
A29: DG / Outages
A31: Tech Manpower
A33: Attendance
A35: Building Master
A37: Calc engine
B99: 🏢 FACILITY SCORECARD (month filter applies • selected facility highlighted • LPCD and kWh/person are per resident student, residences only; SR-1+SR-2 and SR-3+SR-4 are each one block)
B100: Facility | E100: Group | G100: Water kL / mo | I100: Water vs baseline | K100: Water share | M100: Power kWh / mo | O100: Power vs Avg-2025 | Q100: Power share | S100: Water YTD kL | U100: Power YTD kWh | W100: LPCD | Y100: kWh / person
B101: =IF(MIS_Calc!A194="","–",MIS_Calc!A194) -> SR-1 | E101: =IF(MIS_Calc!B194="","–",MIS_Calc!B194) -> Residence | G101: =IF(MIS_Calc!AA194="","–",MIS_Calc!AA194) -> 329 | I101: =IF(MIS_Calc!AC194="","–",MIS_Calc!AC194) -> -0.15315315 | K101: =IF(MIS_Calc!AL194="","–",MIS_Calc!AL194) -> 0.046812749 | M101: =IF(MIS_Calc!AD194="","–",MIS_Calc!AD194) -> 4790 | O101: =IF(MIS_Calc!AF194="","–",MIS_Calc!AF194) -> 0.81990881 | Q101: =IF(MIS_Calc!AM194="","–",MIS_Calc!AM194) -> 0.033102972 | S101: =IF(MIS_Calc!AP194="","–",MIS_Calc!AP194) -> 1817 | U101: =IF(MIS_Calc!AQ194="","–",MIS_Calc!AQ194) -> 32957 | W101: =IF(MIS_Calc!AI194="","–",MIS_Calc!AI194) -> 713.01446 | Y101: =IF(MIS_Calc!AJ194="","–",MIS_Calc!AJ194) -> 326.96552
B102: =IF(MIS_Calc!A195="","–",MIS_Calc!A195) -> SR-2 | E102: =IF(MIS_Calc!B195="","–",MIS_Calc!B195) -> Residence | G102: =IF(MIS_Calc!AA195="","–",MIS_Calc!AA195) -> 312 | I102: =IF(MIS_Calc!AC195="","–",MIS_Calc!AC195) -> 0.56521739 | K102: =IF(MIS_Calc!AL195="","–",MIS_Calc!AL195) -> 0.044393853 | M102: =IF(MIS_Calc!AD195="","–",MIS_Calc!AD195) -> 4692 | O102: =IF(MIS_Calc!AF195="","–",MIS_Calc!AF195) -> 0.55034832 | Q102: =IF(MIS_Calc!AM195="","–",MIS_Calc!AM195) -> 0.032425708 | S102: =IF(MIS_Calc!AP195="","–",MIS_Calc!AP195) -> 1531 | U102: =IF(MIS_Calc!AQ195="","–",MIS_Calc!AQ195) -> 33862 | W102: =IF(MIS_Calc!AI195="","–",MIS_Calc!AI195) -> with SR-1 | Y102: =IF(MIS_Calc!AJ195="","–",MIS_Calc!AJ195) -> with SR-1
B103: =IF(MIS_Calc!A196="","–",MIS_Calc!A196) -> SR-3 | E103: =IF(MIS_Calc!B196="","–",MIS_Calc!B196) -> Residence | G103: =IF(MIS_Calc!AA196="","–",MIS_Calc!AA196) -> 64 | I103: =IF(MIS_Calc!AC196="","–",MIS_Calc!AC196) -> -0.62645914 | K103: =IF(MIS_Calc!AL196="","–",MIS_Calc!AL196) -> 0.0091064314 | M103: =IF(MIS_Calc!AD196="","–",MIS_Calc!AD196) -> 5092 | O103: =IF(MIS_Calc!AF196="","–",MIS_Calc!AF196) -> 0.58292316 | Q103: =IF(MIS_Calc!AM196="","–",MIS_Calc!AM196) -> 0.035190048 | S103: =IF(MIS_Calc!AP196="","–",MIS_Calc!AP196) -> 628 | U103: =IF(MIS_Calc!AQ196="","–",MIS_Calc!AQ196) -> 30031 | W103: =IF(MIS_Calc!AI196="","–",MIS_Calc!AI196) -> 252.19941 | Y103: =IF(MIS_Calc!AJ196="","–",MIS_Calc!AJ196) -> 348.48485
B104: =IF(MIS_Calc!A197="","–",MIS_Calc!A197) -> SR-4 | E104: =IF(MIS_Calc!B197="","–",MIS_Calc!B197) -> Residence | G104: =IF(MIS_Calc!AA197="","–",MIS_Calc!AA197) -> 194 | I104: =IF(MIS_Calc!AC197="","–",MIS_Calc!AC197) -> 0.19691517 | K104: =IF(MIS_Calc!AL197="","–",MIS_Calc!AL197) -> 0.02760387 | M104: =IF(MIS_Calc!AD197="","–",MIS_Calc!AD197) -> 6408 | O104: =IF(MIS_Calc!AF197="","–",MIS_Calc!AF197) -> 0.77765448 | Q104: =IF(MIS_Calc!AM197="","–",MIS_Calc!AM197) -> 0.044284727 | S104: =IF(MIS_Calc!AP197="","–",MIS_Calc!AP197) -> 1740 | U104: =IF(MIS_Calc!AQ197="","–",MIS_Calc!AQ197) -> 51868 | W104: =IF(MIS_Calc!AI197="","–",MIS_Calc!AI197) -> with SR-3 | Y104: =IF(MIS_Calc!AJ197="","–",MIS_Calc!AJ197) -> with SR-3
B105: =IF(MIS_Calc!A198="","–",MIS_Calc!A198) -> SR-9/10 A | E105: =IF(MIS_Calc!B198="","–",MIS_Calc!B198) -> Residence | G105: =IF(MIS_Calc!AA198="","–",MIS_Calc!AA198) -> 1468 | I105: =IF(MIS_Calc!AC198="","–",MIS_Calc!AC198) -> 2.2 | K105: =IF(MIS_Calc!AL198="","–",MIS_Calc!AL198) -> 0.20887877 | M105: =IF(MIS_Calc!AD198="","–",MIS_Calc!AD198) -> 3576 | O105: =IF(MIS_Calc!AF198="","–",MIS_Calc!AF198) -> -0.36872952 | Q105: =IF(MIS_Calc!AM198="","–",MIS_Calc!AM198) -> 0.0247132 | S105: =IF(MIS_Calc!AP198="","–",MIS_Calc!AP198) -> 7012 | U105: =IF(MIS_Calc!AQ198="","–",MIS_Calc!AQ198) -> 43986 | W105: =IF(MIS_Calc!AI198="","–",MIS_Calc!AI198) -> 1076.2463 | Y105: =IF(MIS_Calc!AJ198="","–",MIS_Calc!AJ198) -> 81.272727
B106: =IF(MIS_Calc!A199="","–",MIS_Calc!A199) -> SR-9/10 B | E106: =IF(MIS_Calc!B199="","–",MIS_Calc!B199) -> Residence | G106: =IF(MIS_Calc!AA199="","–",MIS_Calc!AA199) -> 45 | I106: =IF(MIS_Calc!AC199="","–",MIS_Calc!AC199) -> -0.90093561 | K106: =IF(MIS_Calc!AL199="","–",MIS_Calc!AL199) -> 0.0064029596 | M106: =IF(MIS_Calc!AD199="","–",MIS_Calc!AD199) -> 12306 | O106: =IF(MIS_Calc!AF199="","–",MIS_Calc!AF199) -> 1.2501577 | Q106: =IF(MIS_Calc!AM199="","–",MIS_Calc!AM199) -> 0.085044921 | S106: =IF(MIS_Calc!AP199="","–",MIS_Calc!AP199) -> 999 | U106: =IF(MIS_Calc!AQ199="","–",MIS_Calc!AQ199) -> 67455 | W106: =IF(MIS_Calc!AI199="","–",MIS_Calc!AI199) -> 85.388994 | Y106: =IF(MIS_Calc!AJ199="","–",MIS_Calc!AJ199) -> 723.88235
B107: =IF(MIS_Calc!A200="","–",MIS_Calc!A200) -> SR-11/12 CA | E107: =IF(MIS_Calc!B200="","–",MIS_Calc!B200) -> Residence | G107: =IF(MIS_Calc!AA200="","–",MIS_Calc!AA200) -> 710 | I107: =IF(MIS_Calc!AC200="","–",MIS_Calc!AC200) -> 1.0805861 | K107: =IF(MIS_Calc!AL200="","–",MIS_Calc!AL200) -> 0.10102447 | M107: =IF(MIS_Calc!AD200="","–",MIS_Calc!AD200) -> 5498 | O107: =IF(MIS_Calc!AF200="","–",MIS_Calc!AF200) -> 0.19537331 | Q107: =IF(MIS_Calc!AM200="","–",MIS_Calc!AM200) -> 0.037995853 | S107: =IF(MIS_Calc!AP200="","–",MIS_Calc!AP200) -> 3147 | U107: =IF(MIS_Calc!AQ200="","–",MIS_Calc!AQ200) -> 50546 | W107: =IF(MIS_Calc!AI200="","–",MIS_Calc!AI200) -> 558.61526 | Y107: =IF(MIS_Calc!AJ200="","–",MIS_Calc!AJ200) -> 134.09756
B108: =IF(MIS_Calc!A201="","–",MIS_Calc!A201) -> SR-11/12 CB | E108: =IF(MIS_Calc!B201="","–",MIS_Calc!B201) -> Residence | G108: =IF(MIS_Calc!AA201="","–",MIS_Calc!AA201) -> 0 | I108: =IF(MIS_Calc!AC201="","–",MIS_Calc!AC201) -> -1 | K108: =IF(MIS_Calc!AL201="","–",MIS_Calc!AL201) -> 0 | M108: =IF(MIS_Calc!AD201="","–",MIS_Calc!AD201) -> 8718 | O108: =IF(MIS_Calc!AF201="","–",MIS_Calc!AF201) -> 0.67562009 | Q108: =IF(MIS_Calc!AM201="","–",MIS_Calc!AM201) -> 0.060248791 | S108: =IF(MIS_Calc!AP201="","–",MIS_Calc!AP201) -> 1205 | U108: =IF(MIS_Calc!AQ201="","–",MIS_Calc!AQ201) -> 68631 | W108: =IF(MIS_Calc!AI201="","–",MIS_Calc!AI201) -> 0 | Y108: =IF(MIS_Calc!AJ201="","–",MIS_Calc!AJ201) -> 311.35714
B109: =IF(MIS_Calc!A202="","–",MIS_Calc!A202) -> Junior School | E109: =IF(MIS_Calc!B202="","–",MIS_Calc!B202) -> Academic | G109: =IF(MIS_Calc!AA202="","–",MIS_Calc!AA202) -> 120 | I109: =IF(MIS_Calc!AC202="","–",MIS_Calc!AC202) -> -0.76608187 | K109: =IF(MIS_Calc!AL202="","–",MIS_Calc!AL202) -> 0.017074559 | M109: =IF(MIS_Calc!AD202="","–",MIS_Calc!AD202) -> 10905 | O109: =IF(MIS_Calc!AF202="","–",MIS_Calc!AF202) -> 0.29232957 | Q109: =IF(MIS_Calc!AM202="","–",MIS_Calc!AM202) -> 0.07536282 | S109: =IF(MIS_Calc!AP202="","–",MIS_Calc!AP202) -> 358 | U109: =IF(MIS_Calc!AQ202="","–",MIS_Calc!AQ202) -> 79142 | W109: =IF(MIS_Calc!AI202="","–",MIS_Calc!AI202) -> – | Y109: =IF(MIS_Calc!AJ202="","–",MIS_Calc!AJ202) -> –
B110: =IF(MIS_Calc!A203="","–",MIS_Calc!A203) -> Senior School 1 & 3 | E110: =IF(MIS_Calc!B203="","–",MIS_Calc!B203) -> Academic | G110: =IF(MIS_Calc!AA203="","–",MIS_Calc!AA203) -> 82 | I110: =IF(MIS_Calc!AC203="","–",MIS_Calc!AC203) -> -0.82419153 | K110: =IF(MIS_Calc!AL203="","–",MIS_Calc!AL203) -> 0.011667615 | M110: =IF(MIS_Calc!AD203="","–",MIS_Calc!AD203) -> 8760 | O110: =IF(MIS_Calc!AF203="","–",MIS_Calc!AF203) -> -0.089507509 | Q110: =IF(MIS_Calc!AM203="","–",MIS_Calc!AM203) -> 0.060539046 | S110: =IF(MIS_Calc!AP203="","–",MIS_Calc!AP203) -> 482 | U110: =IF(MIS_Calc!AQ203="","–",MIS_Calc!AQ203) -> 86779 | W110: =IF(MIS_Calc!AI203="","–",MIS_Calc!AI203) -> – | Y110: =IF(MIS_Calc!AJ203="","–",MIS_Calc!AJ203) -> –
B111: =IF(MIS_Calc!A204="","–",MIS_Calc!A204) -> Senior School 2 | E111: =IF(MIS_Calc!B204="","–",MIS_Calc!B204) -> Academic | G111: =IF(MIS_Calc!AA204="","–",MIS_Calc!AA204) -> 45 | I111: =IF(MIS_Calc!AC204="","–",MIS_Calc!AC204) -> 0.33004926 | K111: =IF(MIS_Calc!AL204="","–",MIS_Calc!AL204) -> 0.0064029596 | M111: =IF(MIS_Calc!AD204="","–",MIS_Calc!AD204) -> 8229 | O111: =IF(MIS_Calc!AF204="","–",MIS_Calc!AF204) -> 0.095046409 | Q111: =IF(MIS_Calc!AM204="","–",MIS_Calc!AM204) -> 0.056869385 | S111: =IF(MIS_Calc!AP204="","–",MIS_Calc!AP204) -> 558 | U111: =IF(MIS_Calc!AQ204="","–",MIS_Calc!AQ204) -> 69436 | W111: =IF(MIS_Calc!AI204="","–",MIS_Calc!AI204) -> – | Y111: =IF(MIS_Calc!AJ204="","–",MIS_Calc!AJ204) -> –
B112: =IF(MIS_Calc!A205="","–",MIS_Calc!A205) -> Academy Building | E112: =IF(MIS_Calc!B205="","–",MIS_Calc!B205) -> Academic | G112: =IF(MIS_Calc!AA205="","–",MIS_Calc!AA205) -> 38 | I112: =IF(MIS_Calc!AC205="","–",MIS_Calc!AC205) -> 3.3428571 | K112: =IF(MIS_Calc!AL205="","–",MIS_Calc!AL205) -> 0.0054069437 | M112: =IF(MIS_Calc!AD205="","–",MIS_Calc!AD205) -> 18300 | O112: =IF(MIS_Calc!AF205="","–",MIS_Calc!AF205) -> -0.0058850158 | Q112: =IF(MIS_Calc!AM205="","–",MIS_Calc!AM205) -> 0.12646856 | S112: =IF(MIS_Calc!AP205="","–",MIS_Calc!AP205) -> 809 | U112: =IF(MIS_Calc!AQ205="","–",MIS_Calc!AQ205) -> 154300 | W112: =IF(MIS_Calc!AI205="","–",MIS_Calc!AI205) -> – | Y112: =IF(MIS_Calc!AJ205="","–",MIS_Calc!AJ205) -> –
... B118: =IF(MIS_Calc!A211="","–",MIS_Calc!A211) -> Laundry | E118: =IF(MIS_Calc!B211="","–",MIS_Calc!B211) -> Support | G118: =IF(MIS_Calc!AA211="","–",MIS_Calc!AA211) -> 135 | I118: =IF(MIS_Calc!AC211="","–",MIS_Calc!AC211) -> – | K118: =IF(MIS_Calc!AL211="","–",MIS_Calc!AL211) -> 0.019208879 | M118: =IF(MIS_Calc!AD211="","–",MIS_Calc!AD211) -> 3382 | O118: =IF(MIS_Calc!AF211="","–",MIS_Calc!AF211) -> 0.24958433 | Q118: =IF(MIS_Calc!AM211="","–",MIS_Calc!AM211) -> 0.023372495 | S118: =IF(MIS_Calc!AP211="","–",MIS_Calc!AP211) -> 690 | U118: =IF(MIS_Calc!AQ211="","–",MIS_Calc!AQ211) -> 23054 | W118: =IF(MIS_Calc!AI211="","–",MIS_Calc!AI211) -> – | Y118: =IF(MIS_Calc!AJ211="","–",MIS_Calc!AJ211) -> –
B119: METERED FACILITIES | G119: =SUM(MIS_Calc!AA194:AA211) -> 7028 | K119: =IF(COUNT(K101:K118)=0,"–",SUM(K101:K118)) -> 1 | M119: =SUM(MIS_Calc!AD194:AD211) -> 144700 | Q119: =IF(COUNT(Q101:Q118)=0,"–",SUM(Q101:Q118)) -> 1 | S119: =SUM(MIS_Calc!AP194:AP211) -> 36687 | U119: =SUM(MIS_Calc!AQ194:AQ211) -> 1083778.7
B121: 🚨 WATCHLIST (live, follows month filter) | N121: 🔎 DATA-QUALITY FINDINGS IN SOURCE SHEETS (please verify)
B122: LPCD vs benchmark (L/person/day) | J122: =MIS_Calc!$F$46 -> 334.15924 | L122: =IF(MIS_Calc!$F$46="","–",IF(MIS_Calc!$F$46>MIS_Calc!$B$8,"▲ Act","✔ OK")) -> ▲ Act | N122: 1. DG Units Generated, Mar–Aug 2026: total units are typed (11–56 kWh) and do not equal 500 kVA + 750 kVA (44–150 kWh), while diesel reads 8,735–17,820 L against 266–1,523 L in Jan–Feb — verify against the DG log.
...

Sheet PerCapita_Pyramid
A1: AKA | B1: ▲ AGA KHAN ACADEMY | PER-CAPITA PERFORMANCE PYRAMID
A2: OFFICIAL MIS | B2: ="Live MIS data Jan-26 to "&MIS_Calc!$B$6&" • "&TEXT(MIS_Calc!$B$15,"#,##0")&" occupants (LPCD sheet) • "&TEXT(MIS_Calc!$B$7,"#,##0")&" m² • 100 = Avg-2025 baseline, above 100 = better" -> Live MIS data Jan-26 to Aug-26 • 1,354 occupants (LPCD sheet) • 52,652 m² • 100 = Avg-2025 baseline, above 100 = better
B4: MONTH | H4: ="Showing: "&MIS_Calc!$B$5&" | population base "&TEXT(MIS_Calc!$B$15,"#,##0")&" persons • "&TEXT(MIS_Calc!$B$14,"0.0")&" days" -> Showing: Aug-26 | population base 1,354 persons • 31.0 days
A5: FM Dashboard | B5: 📅 Select ▸ | D5: Aug-26 | H5: Per-person figures divide by campus occupants from the LPCD sheet; building pyramids use absolute kL / kWh per month (residence LPCD on FM_Dashboard uses the resident-student headcount in Building_Master). KPIs with no data for the month or no 2025 baseline are shown but not scored.
A7: ▶ Per-Capita Pyramid | B7: ▲ PERFORMANCE PYRAMID — apex index → pillars → categories → key per-capita KPIs → operational detail (score 100 = Avg-2025 • above 100 = better)
A9: Monthly KPI | B9: TIER 1 · APEX One composite score for the campus vs its own 2025 performance | K9: ▲ PER-CAPITA PERFORMANCE INDEX | R9: ="Scored on "&SUM(MIS_Calc!$L$279:$L$309)&" core per-capita KPIs across 6 domains"&CHAR(10)&MIS_Calc!E322 -> Scored on 18 core per-capita KPIs across 6 domains 8 better • 4 in line • 7 watch • 7 no data
K10: =IF(MIS_Calc!C322="","–",MIS_Calc!C322) -> 105.20448
A11: Complaints | K11: =MIS_Calc!D322 -> ✔ Better than 2025
K12: =IF(MIS_Calc!C322="","INDEX SCORE • 100 = Avg-2025","INDEX SCORE • 100 = Avg-2025 • "&TEXT(MIS_Calc!C322-100,"+0.0;-0.0;0")&" pts vs 2025") -> INDEX SCORE • 100 = Avg-2025 • +5.2 pts vs 2025
A13: Water - Bldg
B14: TIER 2 · PILLARS Utilities · Sustainability · Operations | H14: ⚡💧 UTILITIES | L14: ☀♻ SUSTAINABILITY | P14: 🛠 OPERATIONS | U14: Pillar = average of its two category scores Colour key (pillar → category → KPI tile → chart): Blue = Utilities • Green = Sustainability Purple = Operations
A15: LPCD | H15: =IF(MIS_Calc!C319="","–",MIS_Calc!C319) -> 121.90229 | L15: =IF(MIS_Calc!C320="","–",MIS_Calc!C320) -> 113.27106 | P15: =IF(MIS_Calc!C321="","–",MIS_Calc!C321) -> 80.44009
H16: =MIS_Calc!D319 -> ✔ Better than 2025 | L16: =MIS_Calc!D320 -> ✔ Better than 2025 | P16: =MIS_Calc!D321 -> ▲ Below 2025
A17: Water Quality | H17: ="PILLAR SCORE = avg(Energy, Water)" -> PILLAR SCORE = avg(Energy, Water) | L17: ="PILLAR SCORE = avg(Solar, Treatment)" -> PILLAR SCORE = avg(Solar, Treatment) | P17: ="PILLAR = avg(Service Desk, People & Cost)" -> PILLAR = avg(Service Desk, People & Cost)
A19: Power | B19: TIER 3 · CATEGORIES 6 MIS domains | E19: ⚡ ENERGY | H19: 💧 WATER | K19: ☀ SOLAR | N19: ♻ TREATMENT & REUSE | Q19: 🎫 SERVICE DESK | T19: 👷 PEOPLE & COST | W19: Score = avg of core KPI scores (each capped 50–150)
E20: =IF(MIS_Calc!C313="","–",MIS_Calc!C313) -> 93.80458 | H20: =IF(MIS_Calc!C314="","–",MIS_Calc!C314) -> 150 | K20: =IF(MIS_Calc!C315="","–",MIS_Calc!C315) -> 128.75928 | N20: =IF(MIS_Calc!C316="","–",MIS_Calc!C316) -> 97.782835 | Q20: =IF(MIS_Calc!C317="","–",MIS_Calc!C317) -> 58.796296 | T20: =IF(MIS_Calc!C318="","–",MIS_Calc!C318) -> 102.08388
A21: EPI | E21: =IF(MIS_Calc!F313="","no data this month",TEXT(MIS_Calc!F313,MIS_Calc!M279)&" kWh/p/mo") -> 108.1 kWh/p/mo | H21: =IF(MIS_Calc!F314="","no data this month",TEXT(MIS_Calc!F314,MIS_Calc!M286)&" LPCD") -> 334.2 LPCD | K21: =IF(MIS_Calc!F315="","no data this month",TEXT(MIS_Calc!F315,MIS_Calc!M292)&" kWh/p/mo") -> 85.6 kWh/p/mo | N21: =IF(MIS_Calc!F316="","no data this month",TEXT(MIS_Calc!F316,MIS_Calc!M288)&" L/p/day STP") -> 63.9 L/p/day STP | Q21: =IF(MIS_Calc!F317="","no data this month",TEXT(MIS_Calc!F317,MIS_Calc!M299)&" /100p/mo") -> 15.95 /100p/mo | T21: =IF(MIS_Calc!F318="",IF(MIS_Calc!C318="","no data this month","OPEX not yet invoiced"),TEXT(MIS_Calc!F318,MIS_Calc!M306)&" ₹ OPEX/p/mo") -> OPEX not yet invoiced
E22: ="SCORE • "&MIS_Calc!G313&" of "&COUNTIFS(MIS_Calc!$B$279:$B$309,MIS_Calc!B313,MIS_Calc!$L$279:$L$309,1)&" KPIs" -> SCORE • 5 of 5 KPIs | H22: ="SCORE • "&MIS_Calc!G314&" of "&COUNTIFS(MIS_Calc!$B$279:$B$309,MIS_Calc!B314,MIS_Calc!$L$279:$L$309,1)&" KPIs" -> SCORE • 2 of 2 KPIs | K22: ="SCORE • "&MIS_Calc!G315&" of "&COUNTIFS(MIS_Calc!$B$279:$B$309,MIS_Calc!B315,MIS_Calc!$L$279:$L$309,1)&" KPIs" -> SCORE • 2 of 2 KPIs | N22: ="SCORE • "&MIS_Calc!G316&" of "&COUNTIFS(MIS_Calc!$B$279:$B$309,MIS_Calc!B316,MIS_Calc!$L$279:$L$309,1)&" KPIs" -> SCORE • 2 of 2 KPIs | Q22: ="SCORE • "&MIS_Calc!G317&" of "&COUNTIFS(MIS_Calc!$B$279:$B$309,MIS_Calc!B317,MIS_Calc!$L$279:$L$309,1)&" KPIs" -> SCORE • 2 of 3 KPIs | T22: ="SCORE • "&MIS_Calc!G318&" of "&COUNTIFS(MIS_Calc!$B$279:$B$309,MIS_Calc!B318,MIS_Calc!$L$279:$L$309,1)&" KPIs" -> SCORE • 1 of 4 KPIs
A23: Power - Bldg
B24: TIER 4 · 12 KEY KPIs grouped by pillar — Utilities (6) · Sustainability (2) · Operations (4) (selected month / YTD average • Δ vs Avg-2025)
A25: Solar | B25: ⚡ Grid kWh | D25: ₹ Energy | F25: ❄ HVAC | H25: 🏢 EPI | J25: 💧 LPCD | L25: ⛲ Borewell | N25: ☀ Solar | P25: ♻ STP | R25: 🎫 Complaints | T25: ✅ Closure | V25: 💰 OPEX | X25: 👷 Staff
B26: =IF(MIS_Calc!E279="","–",MIS_Calc!E279) -> 108.11078 | D26: =IF(MIS_Calc!E280="","–",MIS_Calc!E280) -> 1351.2341 | F26: =IF(MIS_Calc!E282="","–",MIS_Calc!E282) -> 16.217046 | H26: =IF(MIS_Calc!E281="","–",MIS_Calc!E281) -> 2.7801652 | J26: =IF(MIS_Calc!E286="","–",MIS_Calc!E286) -> 334.15924 | L26: =IF(MIS_Calc!E287="","–",MIS_Calc!E287) -> 285.77214 | N26: =IF(MIS_Calc!E292="","–",MIS_Calc!E292) -> 85.606352 | P26: =IF(MIS_Calc!E288="","–",MIS_Calc!E288) -> 63.920522 | R26: =IF(MIS_Calc!E299="","–",MIS_Calc!E299) -> 15.952733 | T26: =IF(MIS_Calc!E300="","–",MIS_Calc!E300) -> 0.67592593 | V26: =IF(MIS_Calc!E306="","–",MIS_Calc!E306) -> – | X26: =IF(MIS_Calc!E308="","–",MIS_Calc!E308) -> 50.148148
A27: HVAC | B27: kWh/p/mo | D27: ₹/p/mo | F27: kWh/p/mo | H27: kWh/m²/mo | J27: L/p/day | L27: L/p/day | N27: kWh/p/mo | P27: L/p/day | R27: /100p/mo | T27: % closed | V27: ₹/p/mo | X27: persons/tech
B28: =IF(MIS_Calc!H279="","–",TEXT(MIS_Calc!H279,"+0%;-0%;0%")&" "&LEFT(MIS_Calc!J279,1)) -> +10% ▲ | D28: =IF(MIS_Calc!H280="","–",TEXT(MIS_Calc!H280,"+0%;-0%;0%")&" "&LEFT(MIS_Calc!J280,1)) -> +5% ▲ | F28: =IF(MIS_Calc!H282="","–",TEXT(MIS_Calc!H282,"+0%;-0%;0%")&" "&LEFT(MIS_Calc!J282,1)) -> +5% ● | H28: =IF(MIS_Calc!H281="","–",TEXT(MIS_Calc!H281,"+0%;-0%;0%")&" "&LEFT(MIS_Calc!J281,1)) -> +10% ▲ | J28: =IF(MIS_Calc!H286="","–",TEXT(MIS_Calc!H286,"+0%;-0%;0%")&" "&LEFT(MIS_Calc!J286,1)) -> -86% ✔ | L28: =IF(MIS_Calc!H287="","–",TEXT(MIS_Calc!H287,"+0%;-0%;0%")&" "&LEFT(MIS_Calc!J287,1)) -> -60% ✔ | N28: =IF(MIS_Calc!H292="","–",TEXT(MIS_Calc!H292,"+0%;-0%;0%")&" "&LEFT(MIS_Calc!J292,1)) -> +35% ✔ | P28: =IF(MIS_Calc!H288="","–",TEXT(MIS_Calc!H288,"+0%;-0%;0%")&" "&LEFT(MIS_Calc!J288,1)) -> -42% ▲ | R28: =IF(MIS_Calc!H299="","–",TEXT(MIS_Calc!H299,"+0%;-0%;0%")&" "&LEFT(MIS_Calc!J299,1)) -> +154% ▲ | T28: =IF(MIS_Calc!H300="","–",TEXT(MIS_Calc!H300,"+0%;-0%;0%")&" "&LEFT(MIS_Calc!J300,1)) -> -32% ▲ | V28: =IF(MIS_Calc!H306="","–",TEXT(MIS_Calc!H306,"+0%;-0%;0%")&" "&LEFT(MIS_Calc!J306,1)) -> – | X28: =IF(MIS_Calc!H308="","–",TEXT(MIS_Calc!H308,"+0%;-0%;0%")&" "&LEFT(MIS_Calc!J308,1)) -> –
A29: DG / Outages | B29: =IF(OR(MIS_Calc!F279="",MIS_Calc!F279="–"),"2025 avg: –","2025 avg: "&TEXT(MIS_Calc!F279,MIS_Calc!M279)) -> 2025 avg: 98.1 | D29: =IF(OR(MIS_Calc!F280="",MIS_Calc!F280="–"),"2025 avg: –","2025 avg: "&TEXT(MIS_Calc!F280,MIS_Calc!M280)) -> 2025 avg: 1,286 | F29: =IF(OR(MIS_Calc!F282="",MIS_Calc!F282="–"),"2025 avg: –","2025 avg: "&TEXT(MIS_Calc!F282,MIS_Calc!M282)) -> 2025 avg: 15.46 | H29: =IF(OR(MIS_Calc!F281="",MIS_Calc!F281="–"),"2025 avg: –","2025 avg: "&TEXT(MIS_Calc!F281,MIS_Calc!M281)) -> 2025 avg: 2.52 | J29: =IF(OR(MIS_Calc!F286="",MIS_Calc!F286="–"),"2025 avg: –","2025 avg: "&TEXT(MIS_Calc!F286,MIS_Calc!M286)) -> 2025 avg: 2432.2 | L29: =IF(OR(MIS_Calc!F287="",MIS_Calc!F287="–"),"2025 avg: –","2025 avg: "&TEXT(MIS_Calc!F287,MIS_Calc!M287)) -> 2025 avg: 718.3 | N29: =IF(OR(MIS_Calc!F292="",MIS_Calc!F292="–"),"2025 avg: –","2025 avg: "&TEXT(MIS_Calc!F292,MIS_Calc!M292)) -> 2025 avg: 63.4 | P29: =IF(OR(MIS_Calc!F288="",MIS_Calc!F288="–"),"2025 avg: –","2025 avg: "&TEXT(MIS_Calc!F288,MIS_Calc!M288)) -> 2025 avg: 110.1 | R29: =IF(OR(MIS_Calc!F299="",MIS_Calc!F299="–"),"2025 avg: –","2025 avg: "&TEXT(MIS_Calc!F299,MIS_Calc!M299)) -> 2025 avg: 6.28 | T29: =IF(OR(MIS_Calc!F300="",MIS_Calc!F300="–"),"2025 avg: –","2025 avg: "&TEXT(MIS_Calc!F300,MIS_Calc!M300)) -> 2025 avg: 100.0% | V29: =IF(OR(MIS_Calc!F306="",MIS_Calc!F306="–"),"2025 avg: –","2025 avg: "&TEXT(MIS_Calc!F306,MIS_Calc!M306)) -> 2025 avg: 1,840 | X29: =IF(OR(MIS_Calc!F308="",MIS_Calc!F308="–"),"2025 avg: –","2025 avg: "&TEXT(MIS_Calc!F308,MIS_Calc!M308)) -> 2025 avg: –
A31: Tech Manpower | B31: TIER 5 · OPERATIONAL DETAIL — pyramids (apex = smallest of the top-10) & butterflies (back-to-back comparisons)
A33: Attendance
A35: Building Master
A37: Calc engine
B93: 💧 WATER HEATMAP — building meter × month (kL) • darker red = higher use • Δ vs median 2023–25 baseline
B94: Building | F94: Jan-26 | G94: Feb-26 | H94: Mar-26 | I94: Apr-26 | J94: May-26 | K94: Jun-26 | L94: Jul-26 | M94: Aug-26 | N94: Sep-26 | O94: Oct-26 | P94: Nov-26 | Q94: Dec-26 | R94: Avg 2026 | T94: Baseline | V94: Δ | X94: Share
B95: =MIS_Calc!A112 -> SR-1 | F95: =IF(MIS_Calc!C112="","",MIS_Calc!C112) -> 264 | G95: =IF(MIS_Calc!D112="","",MIS_Calc!D112) -> 239 | H95: =IF(MIS_Calc!E112="","",MIS_Calc!E112) -> 280 | I95: =IF(MIS_Calc!F112="","",MIS_Calc!F112) -> 201 | J95: =IF(MIS_Calc!G112="","",MIS_Calc!G112) -> 189 | K95: =IF(MIS_Calc!H112="","",MIS_Calc!H112) -> 91 | L95: =IF(MIS_Calc!I112="","",MIS_Calc!I112) -> 224 | M95: =IF(MIS_Calc!J112="","",MIS_Calc!J112) -> 329 | ... Q95: =IF(MIS_Calc!N112="","",MIS_Calc!N112) | R95: =MIS_Calc!W112 -> 227.125 | T95: =IF(MIS_Calc!P112="","–",MIS_Calc!P112) -> 388.5 | V95: =IFERROR(IF(OR(MIS_Calc!W112="",MIS_Calc!P112="",MIS_Calc!P112=0),"–",MIS_Calc!W112/MIS_Calc!P112-1),"–") -> -0.41537967 | X95: =IFERROR(MIS_Calc!W112/SUM(MIS_Calc!$W$112:$W$131),"–") -> 0.04952708
B96: =MIS_Calc!A113 -> SR-2 | F96: =IF(MIS_Calc!C113="","",MIS_Calc!C113) -> 267 | G96: =IF(MIS_Calc!D113="","",MIS_Calc!D113) -> 427 | H96: =IF(MIS_Calc!E113="","",MIS_Calc!E113) -> 111 | I96: =IF(MIS_Calc!F113="","",MIS_Calc!F113) -> 100 | J96: =IF(MIS_Calc!G113="","",MIS_Calc!G113) -> 102 | K96: =IF(MIS_Calc!H113="","",MIS_Calc!H113) -> 87 | L96: =IF(MIS_Calc!I113="","",MIS_Calc!I113) -> 125 | M96: =IF(MIS_Calc!J113="","",MIS_Calc!J113) -> 312 | ... Q96: =IF(MIS_Calc!N113="","",MIS_Calc!N113) | R96: =MIS_Calc!W113 -> 191.375 | T96: =IF(MIS_Calc!P113="","–",MIS_Calc!P113) -> 199.33333 | V96: =IFERROR(IF(OR(MIS_Calc!W113="",MIS_Calc!P113="",MIS_Calc!P113=0),"–",MIS_Calc!W113/MIS_Calc!P113-1),"–") -> -0.039924749 | X96: =IFERROR(MIS_Calc!W113/SUM(MIS_Calc!$W$112:$W$131),"–") -> 0.041731403
B97: =MIS_Calc!A114 -> SR-3 | F97: =IF(MIS_Calc!C114="","",MIS_Calc!C114) -> 205 | G97: =IF(MIS_Calc!D114="","",MIS_Calc!D114) -> 111 | H97: =IF(MIS_Calc!E114="","",MIS_Calc!E114) -> 8 | I97: =IF(MIS_Calc!F114="","",MIS_Calc!F114) -> 60 | J97: =IF(MIS_Calc!G114="","",MIS_Calc!G114) -> 58 | K97: =IF(MIS_Calc!H114="","",MIS_Calc!H114) -> 60 | L97: =IF(MIS_Calc!I114="","",MIS_Calc!I114) -> 62 | M97: =IF(MIS_Calc!J114="","",MIS_Calc!J114) -> 64 | ... Q97: =IF(MIS_Calc!N114="","",MIS_Calc!N114) | R97: =MIS_Calc!W114 -> 78.5 | T97: =IF(MIS_Calc!P114="","–",MIS_Calc!P114) -> 171.33333 | V97: =IFERROR(IF(OR(MIS_Calc!W114="",MIS_Calc!P114="",MIS_Calc!P114=0),"–",MIS_Calc!W114/MIS_Calc!P114-1),"–") -> -0.54182879 | X97: =IFERROR(MIS_Calc!W114/SUM(MIS_Calc!$W$112:$W$131),"–") -> 0.01711778
B98: =MIS_Calc!A115 -> SR-4 | F98: =IF(MIS_Calc!C115="","",MIS_Calc!C115) -> 136 | G98: =IF(MIS_Calc!D115="","",MIS_Calc!D115) -> 136 | H98: =IF(MIS_Calc!E115="","",MIS_Calc!E115) -> 337 | I98: =IF(MIS_Calc!F115="","",MIS_Calc!F115) -> 337 | J98: =IF(MIS_Calc!G115="","",MIS_Calc!G115) -> 233 | K98: =IF(MIS_Calc!H115="","",MIS_Calc!H115) -> 221 | L98: =IF(MIS_Calc!I115="","",MIS_Calc!I115) -> 146 | M98: =IF(MIS_Calc!J115="","",MIS_Calc!J115) -> 194 | ... Q98: =IF(MIS_Calc!N115="","",MIS_Calc!N115) | R98: =MIS_Calc!W115 -> 217.5 | T98: =IF(MIS_Calc!P115="","–",MIS_Calc!P115) -> 162.08333 | V98: =IFERROR(IF(OR(MIS_Calc!W115="",MIS_Calc!P115="",MIS_Calc!P115=0),"–",MIS_Calc!W115/MIS_Calc!P115-1),"–") -> 0.34190231 | X98: =IFERROR(MIS_Calc!W115/SUM(MIS_Calc!$W$112:$W$131),"–") -> 0.047428244
B99: =MIS_Calc!A116 -> SR-9-10B1A | F99: =IF(MIS_Calc!C116="","",MIS_Calc!C116) -> 568 | G99: =IF(MIS_Calc!D116="","",MIS_Calc!D116) -> 716 | H99: =IF(MIS_Calc!E116="","",MIS_Calc!E116) -> 835 | I99: =IF(MIS_Calc!F116="","",MIS_Calc!F116) -> 1045 | J99: =IF(MIS_Calc!G116="","",MIS_Calc!G116) -> 781 | K99: =IF(MIS_Calc!H116="","",MIS_Calc!H116) -> 279 | L99: =IF(MIS_Calc!I116="","",MIS_Calc!I116) -> 1320 | M99: =IF(MIS_Calc!J116="","",MIS_Calc!J116) -> 1468 | ... Q99: =IF(MIS_Calc!N116="","",MIS_Calc!N116) | R99: =MIS_Calc!W116 -> 876.5 | T99: =IF(MIS_Calc!P116="","–",MIS_Calc!P116) -> 458.75 | V99: =IFERROR(IF(OR(MIS_Calc!W116="",MIS_Calc!P116="",MIS_Calc!P116=0),"–",MIS_Calc!W116/MIS_Calc!P116-1),"–") -> 0.9106267 | X99: =IFERROR(MIS_Calc!W116/SUM(MIS_Calc!$W$112:$W$131),"–") -> 0.19113037
B100: =MIS_Calc!A117 -> SR-9-10B1B | F100: =IF(MIS_Calc!C117="","",MIS_Calc!C117) -> 209 | G100: =IF(MIS_Calc!D117="","",MIS_Calc!D117) -> 73 | H100: =IF(MIS_Calc!E117="","",MIS_Calc!E117) -> 268 | I100: =IF(MIS_Calc!F117="","",MIS_Calc!F117) -> 149 | J100: =IF(MIS_Calc!G117="","",MIS_Calc!G117) -> 167 | K100: =IF(MIS_Calc!H117="","",MIS_Calc!H117) -> 46 | L100: =IF(MIS_Calc!I117="","",MIS_Calc!I117) -> 42 | M100: =IF(MIS_Calc!J117="","",MIS_Calc!J117) -> 45 | ... Q100: =IF(MIS_Calc!N117="","",MIS_Calc!N117) | R100: =MIS_Calc!W117 -> 124.875 | T100: =IF(MIS_Calc!P117="","–",MIS_Calc!P117) -> 454.25 | V100: =IFERROR(IF(OR(MIS_Calc!W117="",MIS_Calc!P117="",MIS_Calc!P117=0),"–",MIS_Calc!W117/MIS_Calc!P117-1),"–") -> -0.72509631 | X100: =IFERROR(MIS_Calc!W117/SUM(MIS_Calc!$W$112:$W$131),"–") -> 0.027230354
B101: =MIS_Calc!A118 -> SR-11-12CA | F101: =IF(MIS_Calc!C118="","",MIS_Calc!C118) -> 233 | G101: =IF(MIS_Calc!D118="","",MIS_Calc!D118) -> 285 | H101: =IF(MIS_Calc!E118="","",MIS_Calc!E118) -> 337 | I101: =IF(MIS_Calc!F118="","",MIS_Calc!F118) -> 377 | J101: =IF(MIS_Calc!G118="","",MIS_Calc!G118) -> 358 | K101: =IF(MIS_Calc!H118="","",MIS_Calc!H118) -> 200 | L101: =IF(MIS_Calc!I118="","",MIS_Calc!I118) -> 647 | M101: =IF(MIS_Calc!J118="","",MIS_Calc!J118) -> 710 | ... Q101: =IF(MIS_Calc!N118="","",MIS_Calc!N118) | R101: =MIS_Calc!W118 -> 393.375 | T101: =IF(MIS_Calc!P118="","–",MIS_Calc!P118) -> 341.25 | V101: =IFERROR(IF(OR(MIS_Calc!W118="",MIS_Calc!P118="",MIS_Calc!P118=0),"–",MIS_Calc!W118/MIS_Calc!P118-1),"–") -> 0.15274725 | X101: =IFERROR(MIS_Calc!W118/SUM(MIS_Calc!$W$112:$W$131),"–") -> 0.085779704
B102: =MIS_Calc!A119 -> SR-11-12CB | F102: =IF(MIS_Calc!C119="","",MIS_Calc!C119) -> 0 | G102: =IF(MIS_Calc!D119="","",MIS_Calc!D119) -> 101 | H102: =IF(MIS_Calc!E119="","",MIS_Calc!E119) -> 450 | I102: =IF(MIS_Calc!F119="","",MIS_Calc!F119) -> 399 | J102: =IF(MIS_Calc!G119="","",MIS_Calc!G119) -> 205 | K102: =IF(MIS_Calc!H119="","",MIS_Calc!H119) -> 50 | L102: =IF(MIS_Calc!I119="","",MIS_Calc!I119) -> 0 | M102: =IF(MIS_Calc!J119="","",MIS_Calc!J119) -> 0 | ... Q102: =IF(MIS_Calc!N119="","",MIS_Calc!N119) | R102: =MIS_Calc!W119 -> 150.625 | T102: =IF(MIS_Calc!P119="","–",MIS_Calc!P119) -> 463.08333 | V102: =IFERROR(IF(OR(MIS_Calc!W119="",MIS_Calc!P119="",MIS_Calc!P119=0),"–",MIS_Calc!W119/MIS_Calc!P119-1),"–") -> -0.67473457 | X102: =IFERROR(MIS_Calc!W119/SUM(MIS_Calc!$W$112:$W$131),"–") -> 0.032845422
B103: =MIS_Calc!A120 -> Junior School-1&2 | F103: =IF(MIS_Calc!C120="","",MIS_Calc!C120) -> 0 | G103: =IF(MIS_Calc!D120="","",MIS_Calc!D120) -> 0 | H103: =IF(MIS_Calc!E120="","",MIS_Calc!E120) -> 1 | I103: =IF(MIS_Calc!F120="","",MIS_Calc!F120) -> 0 | J103: =IF(MIS_Calc!G120="","",MIS_Calc!G120) -> 0 | K103: =IF(MIS_Calc!H120="","",MIS_Calc!H120) -> 1 | L103: =IF(MIS_Calc!I120="","",MIS_Calc!I120) -> 0 | M103: =IF(MIS_Calc!J120="","",MIS_Calc!J120) -> 0 | ... Q103: =IF(MIS_Calc!N120="","",MIS_Calc!N120) | R103: =MIS_Calc!W120 -> 0.25 | T103: =IF(MIS_Calc!P120="","–",MIS_Calc!P120) -> 204.33333 | V103: =IFERROR(IF(OR(MIS_Calc!W120="",MIS_Calc!P120="",MIS_Calc!P120=0),"–",MIS_Calc!W120/MIS_Calc!P120-1),"–") -> -0.99877651 | X103: =IFERROR(MIS_Calc!W120/SUM(MIS_Calc!$W$112:$W$131),"–") -> 5.4515223e-05
...

Sheet Complaints summary
A1: COMPLAINTS SUMMARY · Service Desk Performance 2026 vs 2023–2025
B3: Month | C3: Number of complains received | D3: Priority | F3: Complaints closed | G3: % Emergency | H3: %Non-Critical | I3: Pending | J3: Daily average Nos of Complaints
D4: Emergency | E4: Non Critical
B5: Avg 2023 | C5: 156.75 | D5: 46.5 | E5: 110.25 | F5: 155 | G5: =IF(OR(C5="",C5=0),"",D5/C5) -> 0.29665072 | H5: =IF(OR(C5="",C5=0),"",E5/C5) -> 0.70334928 | I5: 0 | J5: 5.1271825
B6: Avg 2024 | C6: 144.58333 | D6: 1.6666667 | E6: 142.91667 | F6: 142.5 | G6: =IF(OR(C6="",C6=0),"",D6/C6) -> 0.011527378 | H6: =IF(OR(C6="",C6=0),"",E6/C6) -> 0.98847262 | I6: 0 | J6: 4.6639785
B7: Avg 2025 | C7: 85 | D7: 2 | E7: 83 | F7: 85 | G7: =IF(OR(C7="",C7=0),"",D7/C7) -> 0.023529412 | H7: =IF(OR(C7="",C7=0),"",E7/C7) -> 0.97647059 | I7: 0 | J7: 2.7715054
B8: 46023 | C8: 144 | D8: 8 | E8: 122 | F8: 139 | G8: =IF(OR(C8="",C8=0),"",D8/C8) -> 0.055555556 | H8: =IF(OR(C8="",C8=0),"",E8/C8) -> 0.84722222 | I8: 1 | J8: =IF(C8="","",C8/DAY(EOMONTH(B8,0))) -> 4.6451613
B9: 46054 | C9: 122 | D9: 0 | E9: 122 | F9: 119 | G9: =IF(OR(C9="",C9=0),"",D9/C9) -> 0 | H9: =IF(OR(C9="",C9=0),"",E9/C9) -> 1 | I9: 3 | J9: =IF(C9="","",C9/DAY(EOMONTH(B9,0))) -> 4.3571429
B10: 46082 | G10: =IF(OR(C10="",C10=0),"",D10/C10) | H10: =IF(OR(C10="",C10=0),"",E10/C10) | J10: =IF(C10="","",C10/DAY(EOMONTH(B10,0)))
B11: 46113 | G11: =IF(OR(C11="",C11=0),"",D11/C11) | H11: =IF(OR(C11="",C11=0),"",E11/C11) | J11: =IF(C11="","",C11/DAY(EOMONTH(B11,0)))
B12: 46143 | G12: =IF(OR(C12="",C12=0),"",D12/C12) | H12: =IF(OR(C12="",C12=0),"",E12/C12) | J12: =IF(C12="","",C12/DAY(EOMONTH(B12,0)))
B13: 46174 | C13: 155 | D13: 5 | E13: 150 | F13: 155 | G13: =IF(OR(C13="",C13=0),"",D13/C13) -> 0.032258065 | H13: =IF(OR(C13="",C13=0),"",E13/C13) -> 0.96774194 | J13: =IF(C13="","",C13/DAY(EOMONTH(B13,0))) -> 5.1666667
B14: 46204 | C14: 168 | D14: 6 | E14: 162 | F14: 127 | G14: =IF(OR(C14="",C14=0),"",D14/C14) -> 0.035714286 | H14: =IF(OR(C14="",C14=0),"",E14/C14) -> 0.96428571 | J14: =IF(C14="","",C14/DAY(EOMONTH(B14,0))) -> 5.4193548
B15: 46235 | C15: 216 | D15: 7 | E15: 156 | F15: 146 | G15: =IF(OR(C15="",C15=0),"",D15/C15) -> 0.032407407 | H15: =IF(OR(C15="",C15=0),"",E15/C15) -> 0.72222222 | J15: =IF(C15="","",C15/DAY(EOMONTH(B15,0))) -> 6.9677419
B16: 46266 | G16: =IF(OR(C16="",C16=0),"",D16/C16) | H16: =IF(OR(C16="",C16=0),"",E16/C16) | J16: =IF(C16="","",C16/DAY(EOMONTH(B16,0)))
B17: 46296 | G17: =IF(OR(C17="",C17=0),"",D17/C17) | H17: =IF(OR(C17="",C17=0),"",E17/C17) | J17: =IF(C17="","",C17/DAY(EOMONTH(B17,0)))
B18: 46327 | G18: =IF(OR(C18="",C18=0),"",D18/C18) | H18: =IF(OR(C18="",C18=0),"",E18/C18) | J18: =IF(C18="","",C18/DAY(EOMONTH(B18,0)))
B19: 46357 | G19: =IF(OR(C19="",C19=0),"",D19/C19) | H19: =IF(OR(C19="",C19=0),"",E19/C19) | J19: =IF(C19="","",C19/DAY(EOMONTH(B19,0)))
B20: Avg 2026 | C20: =IFERROR(AVERAGE(C8:C19),"") -> 161 | D20: =IFERROR(AVERAGE(D8:D19),"") -> 5.2 | E20: =IFERROR(AVERAGE(E8:E19),"") -> 142.4 | F20: =IFERROR(AVERAGE(F8:F19),"") -> 137.2 | G20: =IFERROR(SUM(D8:D19)/SUM(C8:C19),"") -> 0.032298137 | H20: =IFERROR(SUM(E8:E19)/SUM(C8:C19),"") -> 0.88447205 | I20: =IFERROR(AVERAGE(I8:I19),"") -> 2 | J20: =IFERROR(AVERAGE(J8:J19),"") -> 5.3112135
B21: Total 2026 YTD | C21: =SUM(C8:C19) -> 805 | D21: =SUM(D8:D19) -> 26 | E21: =SUM(E8:E19) -> 712 | F21: =SUM(F8:F19) -> 686 | I21: =SUM(I8:I19) -> 4
O26: AUDIT SNAPSHOT (live)
O27: AUDIT SNAPSHOT | P27: Baseline | Q27: Current (latest)
O28: Total Complaints | P28: 111 | Q28: =IFERROR(INDEX(C8:C19,MATCH(9.99E+307,C8:C19)),"") -> 216
O29: Completed | P29: 111 | Q29: =IFERROR(INDEX(F8:F19,MATCH(9.99E+307,C8:C19)),"") -> 146
O30: Pending | P30: 0 | Q30: =IFERROR(INDEX(I8:I19,MATCH(9.99E+307,C8:C19)),"") -> 0

Sheet Building wise water
B1: BUILDING-WISE WATER CONSUMPTION (kL) · 2026 monthly vs 2023–2025 averages
B2: Flow hierarchy: Borewells + STP outlet → WTP / drip irrigation / sports field → building sub-meters downstream of WTP. Blue = monthly meter entry · Baseline = MEDIAN of the 2023–25 monthly averages (robust to the suspect Avg-2025 building values) · tiles follow the month selected on FM_Dashboard (latest logged month when 2026 YTD is selected).
B4: ="BUILDINGS · "&UPPER(SUBSTITUTE(INDEX($I$9:$T$9,IFERROR(MATCH(MIS_Calc!$B$3,$I$9:$T$9,0),IFERROR(MATCH(9.99E+307,$I$31:$T$31),1))),"-"," 20"))&" (kL)" -> BUILDINGS · AUG 2026 (kL) | E4: BUILDINGS · 2026 YTD AVG (kL/month) | I4: ="WTP OUTPUT · "&UPPER(SUBSTITUTE(INDEX($I$9:$T$9,IFERROR(MATCH(MIS_Calc!$B$3,$I$9:$T$9,0),IFERROR(MATCH(9.99E+307,$I$31:$T$31),1))),"-"," 20"))&" (kL)" -> WTP OUTPUT · AUG 2026 (kL) | N4: TOP BUILDING · 2026 YTD AVG | S4: METERS REPORTING · SELECTED MONTH | W4: DATA-QUALITY FLAGS OPEN
B5: =IF(INDEX($I$31:$T$31,IFERROR(MATCH(MIS_Calc!$B$3,$I$9:$T$9,0),IFERROR(MATCH(9.99E+307,$I$31:$T$31),1)))="","—",INDEX($I$31:$T$31,IFERROR(MATCH(MIS_Calc!$B$3,$I$9:$T$9,0),IFERROR(MATCH(9.99E+307,$I$31:$T$31),1)))) -> 7028 | E5: =IF($U$31="","—",$U$31) -> 4585.875 | I5: =IF(INDEX($I$33:$T$33,IFERROR(MATCH(MIS_Calc!$B$3,$I$9:$T$9,0),IFERROR(MATCH(9.99E+307,$I$31:$T$31),1)))="","—",INDEX($I$33:$T$33,IFERROR(MATCH(MIS_Calc!$B$3,$I$9:$T$9,0),IFERROR(MATCH(9.99E+307,$I$31:$T$31),1)))) -> 10986 | N5: =INDEX($C$11:$C$30,MATCH(MAX($U$11:$U$30),$U$11:$U$30,0)) -> SR-9-10B1A | S5: =INDEX($I$45:$T$45,IFERROR(MATCH(MIS_Calc!$B$3,$I$9:$T$9,0),IFERROR(MATCH(9.99E+307,$I$31:$T$31),1))) -> 24 | W5: =COUNTIF($Z$11:$Z$39,"?*")-COUNTIF($Z$11:$Z$39,"OK") -> 14
B7: =IF(OR(INDEX($I$31:$T$31,IFERROR(MATCH(MIS_Calc!$B$3,$I$9:$T$9,0),IFERROR(MATCH(9.99E+307,$I$31:$T$31),1)))="",$H$31=""),"no reading for this month","vs baseline "&TEXT(INDEX($I$31:$T$31,IFERROR(MATCH(MIS_Calc!$B$3,$I$9:$T$9,0),IFERROR(MATCH(9.99E+307,$I$31:$T$31),1)))/$H$31-1,"+0%;-0%")) -> vs baseline +19% | E7: =IF($X$31="","","vs baseline "&TEXT($X$31,"+0%;-0%")&" · "&COUNT($I$31:$T$31)&" months logged") -> vs baseline -22% · 8 months logged | I7: =IF(INDEX($I$44:$T$44,IFERROR(MATCH(MIS_Calc!$B$3,$I$9:$T$9,0),IFERROR(MATCH(9.99E+307,$I$31:$T$31),1)))="","coverage n/a","building meters cover "&TEXT(INDEX($I$44:$T$44,IFERROR(MATCH(MIS_Calc!$B$3,$I$9:$T$9,0),IFERROR(MATCH(9.99E+307,$I$31:$T$31),1))),"0%")&" of WTP output") -> building meters cover 64% of WTP output | N7: =TEXT(MAX($U$11:$U$30),"#,##0")&" kL/month · "&TEXT(MAX($U$11:$U$30)/$U$31,"0%")&" of building use" -> 877 kL/month · 19% of building use | S7: ="latest month logged: "&IFERROR(INDEX($I$9:$T$9,MATCH(9.99E+307,$I$31:$T$31)),"—") -> latest month logged: Aug-26 | W7: =COUNTIF($Z$11:$Z$39,"VERIFY*")&" verify Avg-2025 · "&COUNTIF($Z$11:$Z$39,"MISSING*")&" missing month(s) · "&(COUNTIF($Z$11:$Z$39,"?*")-COUNTIF($Z$11:$Z$39,"OK")-COUNTIF($Z$11:$Z$39,"VERIFY*")-COUNTIF($Z$11:$Z$39,"MISSING*"))&" other" -> 13 verify Avg-2025 · 1 missing month(s) · 0 other
B9: S No | C9: Location | D9: Group | E9: Avg 2023 | F9: Avg 2024 | G9: Avg 2025 | H9: Baseline (median 23–25) | I9: Jan-26 | J9: Feb-26 | K9: Mar-26 | L9: Apr-26 | M9: May-26 | N9: Jun-26 | O9: Jul-26 | P9: Aug-26 | Q9: Sep-26 | R9: Oct-26 | S9: Nov-26 | T9: Dec-26 | U9: Avg 2026 YTD | V9: Total 2026 YTD | W9: Δ YTD vs Avg 2025 | X9: Δ YTD vs Baseline | Y9: Months logged | Z9: Data-quality flag
B10: A · BUILDING SUB-METERS (downstream of WTP)
B11: 1 | C11: SR-1 | D11: Residence | E11: 145.16667 | F11: 388.5 | G11: 1180.5833 | H11: =IF(COUNT(E11:G11)=0,"",MEDIAN(E11:G11)) -> 388.5 | I11: 264 | J11: 239 | K11: 280 | L11: 201 | M11: 189 | N11: 91 | O11: 224 | P11: 329 | U11: =IF(COUNT(I11:T11)=0,"",AVERAGE(I11:T11)) -> 227.125 | V11: =IF(COUNT(I11:T11)=0,"",SUM(I11:T11)) -> 1817 | W11: =IF(OR(U11="",N(G11)=0),"",U11/G11-1) -> -0.80761629 | X11: =IF(OR(U11="",N(H11)=0),"",U11/H11-1) -> -0.41537967 | Y11: =COUNT(I11:T11) -> 8 | Z11: =IF(COUNT(I11:T11)=0,"NO 2026 DATA",IF(COUNT(I11:T11)<MATCH(9.99E+307,I11:T11)-MATCH(TRUE,INDEX(ISNUMBER(I11:T11),0),0)+1,"MISSING MONTH(S)",IF(AND(COUNT(E11:F11)=2,N(G11)>3*MAX(E11:F11)),"VERIFY AVG-2025 (>3× prior yrs)",IF(AND(N(H11)>=500,MIN(I11:T11)<0.1*N(H11)),"CHECK OUTLIER MONTH",IF(AND(N(H11)>=50,LOOKUP(9.99E+307,I11:T11)=0),"LATEST = 0 · CHECK METER","OK"))))) -> VERIFY AVG-2025 (>3× prior yrs)
B12: 2 | C12: SR-2 | D12: Residence | E12: 178.58333 | F12: 199.33333 | G12: 1194.8333 | H12: =IF(COUNT(E12:G12)=0,"",MEDIAN(E12:G12)) -> 199.33333 | I12: 267 | J12: 427 | K12: 111 | L12: 100 | M12: 102 | N12: 87 | O12: 125 | P12: 312 | U12: =IF(COUNT(I12:T12)=0,"",AVERAGE(I12:T12)) -> 191.375 | V12: =IF(COUNT(I12:T12)=0,"",SUM(I12:T12)) -> 1531 | W12: =IF(OR(U12="",N(G12)=0),"",U12/G12-1) -> -0.83983122 | X12: =IF(OR(U12="",N(H12)=0),"",U12/H12-1) -> -0.039924749 | Y12: =COUNT(I12:T12) -> 8 | Z12: =IF(COUNT(I12:T12)=0,"NO 2026 DATA",IF(COUNT(I12:T12)<MATCH(9.99E+307,I12:T12)-MATCH(TRUE,INDEX(ISNUMBER(I12:T12),0),0)+1,"MISSING MONTH(S)",IF(AND(COUNT(E12:F12)=2,N(G12)>3*MAX(E12:F12)),"VERIFY AVG-2025 (>3× prior yrs)",IF(AND(N(H12)>=500,MIN(I12:T12)<0.1*N(H12)),"CHECK OUTLIER MONTH",IF(AND(N(H12)>=50,LOOKUP(9.99E+307,I12:T12)=0),"LATEST = 0 · CHECK METER","OK"))))) -> VERIFY AVG-2025 (>3× prior yrs)
B13: 3 | C13: SR-3 | D13: Residence | E13: 103.08333 | F13: 171.33333 | G13: 1274.9167 | H13: =IF(COUNT(E13:G13)=0,"",MEDIAN(E13:G13)) -> 171.33333 | I13: 205 | J13: 111 | K13: 8 | L13: 60 | M13: 58 | N13: 60 | O13: 62 | P13: 64 | U13: =IF(COUNT(I13:T13)=0,"",AVERAGE(I13:T13)) -> 78.5 | V13: =IF(COUNT(I13:T13)=0,"",SUM(I13:T13)) -> 628 | W13: =IF(OR(U13="",N(G13)=0),"",U13/G13-1) -> -0.93842735 | X13: =IF(OR(U13="",N(H13)=0),"",U13/H13-1) -> -0.54182879 | Y13: =COUNT(I13:T13) -> 8 | Z13: =IF(COUNT(I13:T13)=0,"NO 2026 DATA",IF(COUNT(I13:T13)<MATCH(9.99E+307,I13:T13)-MATCH(TRUE,INDEX(ISNUMBER(I13:T13),0),0)+1,"MISSING MONTH(S)",IF(AND(COUNT(E13:F13)=2,N(G13)>3*MAX(E13:F13)),"VERIFY AVG-2025 (>3× prior yrs)",IF(AND(N(H13)>=500,MIN(I13:T13)<0.1*N(H13)),"CHECK OUTLIER MONTH",IF(AND(N(H13)>=50,LOOKUP(9.99E+307,I13:T13)=0),"LATEST = 0 · CHECK METER","OK"))))) -> VERIFY AVG-2025 (>3× prior yrs)
B14: 4 | C14: SR-4 | D14: Residence | E14: 105.5 | F14: 162.08333 | G14: 1677.1667 | H14: =IF(COUNT(E14:G14)=0,"",MEDIAN(E14:G14)) -> 162.08333 | I14: 136 | J14: 136 | K14: 337 | L14: 337 | M14: 233 | N14: 221 | O14: 146 | P14: 194 | U14: =IF(COUNT(I14:T14)=0,"",AVERAGE(I14:T14)) -> 217.5 | V14: =IF(COUNT(I14:T14)=0,"",SUM(I14:T14)) -> 1740 | W14: =IF(OR(U14="",N(G14)=0),"",U14/G14-1) -> -0.870317 | X14: =IF(OR(U14="",N(H14)=0),"",U14/H14-1) -> 0.34190231 | Y14: =COUNT(I14:T14) -> 8 | Z14: =IF(COUNT(I14:T14)=0,"NO 2026 DATA",IF(COUNT(I14:T14)<MATCH(9.99E+307,I14:T14)-MATCH(TRUE,INDEX(ISNUMBER(I14:T14),0),0)+1,"MISSING MONTH(S)",IF(AND(COUNT(E14:F14)=2,N(G14)>3*MAX(E14:F14)),"VERIFY AVG-2025 (>3× prior yrs)",IF(AND(N(H14)>=500,MIN(I14:T14)<0.1*N(H14)),"CHECK OUTLIER MONTH",IF(AND(N(H14)>=50,LOOKUP(9.99E+307,I14:T14)=0),"LATEST = 0 · CHECK METER","OK"))))) -> VERIFY AVG-2025 (>3× prior yrs)
B15: 5 | C15: SR-9-10B1A | D15: Residence | E15: 455.5 | F15: 458.75 | G15: 2503.1667 | H15: =IF(COUNT(E15:G15)=0,"",MEDIAN(E15:G15)) -> 458.75 | I15: 568 | J15: 716 | K15: 835 | L15: 1045 | M15: 781 | N15: 279 | O15: 1320 | P15: 1468 | U15: =IF(COUNT(I15:T15)=0,"",AVERAGE(I15:T15)) -> 876.5 | V15: =IF(COUNT(I15:T15)=0,"",SUM(I15:T15)) -> 7012 | W15: =IF(OR(U15="",N(G15)=0),"",U15/G15-1) -> -0.64984353 | X15: =IF(OR(U15="",N(H15)=0),"",U15/H15-1) -> 0.9106267 | Y15: =COUNT(I15:T15) -> 8 | Z15: =IF(COUNT(I15:T15)=0,"NO 2026 DATA",IF(COUNT(I15:T15)<MATCH(9.99E+307,I15:T15)-MATCH(TRUE,INDEX(ISNUMBER(I15:T15),0),0)+1,"MISSING MONTH(S)",IF(AND(COUNT(E15:F15)=2,N(G15)>3*MAX(E15:F15)),"VERIFY AVG-2025 (>3× prior yrs)",IF(AND(N(H15)>=500,MIN(I15:T15)<0.1*N(H15)),"CHECK OUTLIER MONTH",IF(AND(N(H15)>=50,LOOKUP(9.99E+307,I15:T15)=0),"LATEST = 0 · CHECK METER","OK"))))) -> VERIFY AVG-2025 (>3× prior yrs)
B16: 6 | C16: SR-9-10B1B | D16: Residence | E16: 415.41667 | F16: 454.25 | G16: 2943.25 | H16: =IF(COUNT(E16:G16)=0,"",MEDIAN(E16:G16)) -> 454.25 | I16: 209 | J16: 73 | K16: 268 | L16: 149 | M16: 167 | N16: 46 | O16: 42 | P16: 45 | U16: =IF(COUNT(I16:T16)=0,"",AVERAGE(I16:T16)) -> 124.875 | V16: =IF(COUNT(I16:T16)=0,"",SUM(I16:T16)) -> 999 | W16: =IF(OR(U16="",N(G16)=0),"",U16/G16-1) -> -0.95757241 | X16: =IF(OR(U16="",N(H16)=0),"",U16/H16-1) -> -0.72509631 | Y16: =COUNT(I16:T16) -> 8 | Z16: =IF(COUNT(I16:T16)=0,"NO 2026 DATA",IF(COUNT(I16:T16)<MATCH(9.99E+307,I16:T16)-MATCH(TRUE,INDEX(ISNUMBER(I16:T16),0),0)+1,"MISSING MONTH(S)",IF(AND(COUNT(E16:F16)=2,N(G16)>3*MAX(E16:F16)),"VERIFY AVG-2025 (>3× prior yrs)",IF(AND(N(H16)>=500,MIN(I16:T16)<0.1*N(H16)),"CHECK OUTLIER MONTH",IF(AND(N(H16)>=50,LOOKUP(9.99E+307,I16:T16)=0),"LATEST = 0 · CHECK METER","OK"))))) -> VERIFY AVG-2025 (>3× prior yrs)
B17: 7 | C17: SR-11-12CA | D17: Residence | E17: 341.25 | F17: 328.75 | G17: 2175.4167 | H17: =IF(COUNT(E17:G17)=0,"",MEDIAN(E17:G17)) -> 341.25 | I17: 233 | J17: 285 | K17: 337 | L17: 377 | M17: 358 | N17: 200 | O17: 647 | P17: 710 | U17: =IF(COUNT(I17:T17)=0,"",AVERAGE(I17:T17)) -> 393.375 | V17: =IF(COUNT(I17:T17)=0,"",SUM(I17:T17)) -> 3147 | W17: =IF(OR(U17="",N(G17)=0),"",U17/G17-1) -> -0.81917257 | X17: =IF(OR(U17="",N(H17)=0),"",U17/H17-1) -> 0.15274725 | Y17: =COUNT(I17:T17) -> 8 | Z17: =IF(COUNT(I17:T17)=0,"NO 2026 DATA",IF(COUNT(I17:T17)<MATCH(9.99E+307,I17:T17)-MATCH(TRUE,INDEX(ISNUMBER(I17:T17),0),0)+1,"MISSING MONTH(S)",IF(AND(COUNT(E17:F17)=2,N(G17)>3*MAX(E17:F17)),"VERIFY AVG-2025 (>3× prior yrs)",IF(AND(N(H17)>=500,MIN(I17:T17)<0.1*N(H17)),"CHECK OUTLIER MONTH",IF(AND(N(H17)>=50,LOOKUP(9.99E+307,I17:T17)=0),"LATEST = 0 · CHECK METER","OK"))))) -> VERIFY AVG-2025 (>3× prior yrs)
B18: 8 | C18: SR-11-12CB | D18: Residence | E18: 388.33333 | F18: 463.08333 | G18: 2811.4167 | H18: =IF(COUNT(E18:G18)=0,"",MEDIAN(E18:G18)) -> 463.08333 | I18: 0 | J18: 101 | K18: 450 | L18: 399 | M18: 205 | N18: 50 | O18: 0 | P18: 0 | U18: =IF(COUNT(I18:T18)=0,"",AVERAGE(I18:T18)) -> 150.625 | V18: =IF(COUNT(I18:T18)=0,"",SUM(I18:T18)) -> 1205 | W18: =IF(OR(U18="",N(G18)=0),"",U18/G18-1) -> -0.94642381 | X18: =IF(OR(U18="",N(H18)=0),"",U18/H18-1) -> -0.67473457 | Y18: =COUNT(I18:T18) -> 8 | Z18: =IF(COUNT(I18:T18)=0,"NO 2026 DATA",IF(COUNT(I18:T18)<MATCH(9.99E+307,I18:T18)-MATCH(TRUE,INDEX(ISNUMBER(I18:T18),0),0)+1,"MISSING MONTH(S)",IF(AND(COUNT(E18:F18)=2,N(G18)>3*MAX(E18:F18)),"VERIFY AVG-2025 (>3× prior yrs)",IF(AND(N(H18)>=500,MIN(I18:T18)<0.1*N(H18)),"CHECK OUTLIER MONTH",IF(AND(N(H18)>=50,LOOKUP(9.99E+307,I18:T18)=0),"LATEST = 0 · CHECK METER","OK"))))) -> VERIFY AVG-2025 (>3× prior yrs)
B19: 9 | C19: Junior School-1&2 | D19: Academic | E19: 177.75 | F19: 204.33333 | G19: 2368.75 | H19: =IF(COUNT(E19:G19)=0,"",MEDIAN(E19:G19)) -> 204.33333 | I19: 0 | J19: 0 | K19: 1 | L19: 0 | M19: 0 | N19: 1 | O19: 0 | P19: 0 | U19: =IF(COUNT(I19:T19)=0,"",AVERAGE(I19:T19)) -> 0.25 | V19: =IF(COUNT(I19:T19)=0,"",SUM(I19:T19)) -> 2 | W19: =IF(OR(U19="",N(G19)=0),"",U19/G19-1) -> -0.99989446 | X19: =IF(OR(U19="",N(H19)=0),"",U19/H19-1) -> -0.99877651 | Y19: =COUNT(I19:T19) -> 8 | Z19: =IF(COUNT(I19:T19)=0,"NO 2026 DATA",IF(COUNT(I19:T19)<MATCH(9.99E+307,I19:T19)-MATCH(TRUE,INDEX(ISNUMBER(I19:T19),0),0)+1,"MISSING MONTH(S)",IF(AND(COUNT(E19:F19)=2,N(G19)>3*MAX(E19:F19)),"VERIFY AVG-2025 (>3× prior yrs)",IF(AND(N(H19)>=500,MIN(I19:T19)<0.1*N(H19)),"CHECK OUTLIER MONTH",IF(AND(N(H19)>=50,LOOKUP(9.99E+307,I19:T19)=0),"LATEST = 0 · CHECK METER","OK"))))) -> VERIFY AVG-2025 (>3× prior yrs)
B20: 10 | C20: Junior School-3 | D20: Academic | E20: 265.33333 | F20: 308.66667 | G20: 6906.1667 | H20: =IF(COUNT(E20:G20)=0,"",MEDIAN(E20:G20)) -> 308.66667 | I20: 27 | J20: 22 | K20: 40 | L20: 25 | M20: 28 | N20: 7 | O20: 87 | P20: 120 | U20: =IF(COUNT(I20:T20)=0,"",AVERAGE(I20:T20)) -> 44.5 | V20: =IF(COUNT(I20:T20)=0,"",SUM(I20:T20)) -> 356 | W20: =IF(OR(U20="",N(G20)=0),"",U20/G20-1) -> -0.99355648 | X20: =IF(OR(U20="",N(H20)=0),"",U20/H20-1) -> -0.85583153 | Y20: =COUNT(I20:T20) -> 8 | Z20: =IF(COUNT(I20:T20)=0,"NO 2026 DATA",IF(COUNT(I20:T20)<MATCH(9.99E+307,I20:T20)-MATCH(TRUE,INDEX(ISNUMBER(I20:T20),0),0)+1,"MISSING MONTH(S)",IF(AND(COUNT(E20:F20)=2,N(G20)>3*MAX(E20:F20)),"VERIFY AVG-2025 (>3× prior yrs)",IF(AND(N(H20)>=500,MIN(I20:T20)<0.1*N(H20)),"CHECK OUTLIER MONTH",IF(AND(N(H20)>=50,LOOKUP(9.99E+307,I20:T20)=0),"LATEST = 0 · CHECK METER","OK"))))) -> VERIFY AVG-2025 (>3× prior yrs)
B21: 11 | C21: Senior School-1 | D21: Academic | E21: 367.5 | F21: 328.41667 | G21: 2929.3333 | H21: =IF(COUNT(E21:G21)=0,"",MEDIAN(E21:G21)) -> 367.5 | I21: 101 | J21: 50 | K21: 61 | L21: 90 | M21: 7 | N21: 0 | O21: 78 | P21: 82 | U21: =IF(COUNT(I21:T21)=0,"",AVERAGE(I21:T21)) -> 58.625 | V21: =IF(COUNT(I21:T21)=0,"",SUM(I21:T21)) -> 469 | W21: =IF(OR(U21="",N(G21)=0),"",U21/G21-1) -> -0.97998691 | X21: =IF(OR(U21="",N(H21)=0),"",U21/H21-1) -> -0.84047619 | Y21: =COUNT(I21:T21) -> 8 | Z21: =IF(COUNT(I21:T21)=0,"NO 2026 DATA",IF(COUNT(I21:T21)<MATCH(9.99E+307,I21:T21)-MATCH(TRUE,INDEX(ISNUMBER(I21:T21),0),0)+1,"MISSING MONTH(S)",IF(AND(COUNT(E21:F21)=2,N(G21)>3*MAX(E21:F21)),"VERIFY AVG-2025 (>3× prior yrs)",IF(AND(N(H21)>=500,MIN(I21:T21)<0.1*N(H21)),"CHECK OUTLIER MONTH",IF(AND(N(H21)>=50,LOOKUP(9.99E+307,I21:T21)=0),"LATEST = 0 · CHECK METER","OK"))))) -> VERIFY AVG-2025 (>3× prior yrs)
B22: 12 | C22: Senior School-2 | D22: Academic | E22: 51.7075 | F22: 19.708333 | G22: 33.833333 | H22: =IF(COUNT(E22:G22)=0,"",MEDIAN(E22:G22)) -> 33.833333 | I22: 33 | J22: 41 | K22: 15 | L22: 121 | M22: 272 | N22: 5 | O22: 26 | P22: 45 | U22: =IF(COUNT(I22:T22)=0,"",AVERAGE(I22:T22)) -> 69.75 | V22: =IF(COUNT(I22:T22)=0,"",SUM(I22:T22)) -> 558 | W22: =IF(OR(U22="",N(G22)=0),"",U22/G22-1) -> 1.0615764 | X22: =IF(OR(U22="",N(H22)=0),"",U22/H22-1) -> 1.0615764 | Y22: =COUNT(I22:T22) -> 8 | Z22: =IF(COUNT(I22:T22)=0,"NO 2026 DATA",IF(COUNT(I22:T22)<MATCH(9.99E+307,I22:T22)-MATCH(TRUE,INDEX(ISNUMBER(I22:T22),0),0)+1,"MISSING MONTH(S)",IF(AND(COUNT(E22:F22)=2,N(G22)>3*MAX(E22:F22)),"VERIFY AVG-2025 (>3× prior yrs)",IF(AND(N(H22)>=500,MIN(I22:T22)<0.1*N(H22)),"CHECK OUTLIER MONTH",IF(AND(N(H22)>=50,LOOKUP(9.99E+307,I22:T22)=0),"LATEST = 0 · CHECK METER","OK"))))) -> OK
... B28: 18 | C28: PCM | D28: Support | E28: 1081.6667 | F28: 1140.6667 | G28: 1193 | H28: =IF(COUNT(E28:G28)=0,"",MEDIAN(E28:G28)) -> 1140.6667 | I28: 468 | J28: 497 | K28: 520 | L28: 468 | M28: 445 | N28: 589 | O28: 598 | P28: 570 | U28: =IF(COUNT(I28:T28)=0,"",AVERAGE(I28:T28)) -> 519.375 | V28: =IF(COUNT(I28:T28)=0,"",SUM(I28:T28)) -> 4155 | W28: =IF(OR(U28="",N(G28)=0),"",U28/G28-1) -> -0.56464795 | X28: =IF(OR(U28="",N(H28)=0),"",U28/H28-1) -> -0.54467417 | Y28: =COUNT(I28:T28) -> 8 | Z28: =IF(COUNT(I28:T28)=0,"NO 2026 DATA",IF(COUNT(I28:T28)<MATCH(9.99E+307,I28:T28)-MATCH(TRUE,INDEX(ISNUMBER(I28:T28),0),0)+1,"MISSING MONTH(S)",IF(AND(COUNT(E28:F28)=2,N(G28)>3*MAX(E28:F28)),"VERIFY AVG-2025 (>3× prior yrs)",IF(AND(N(H28)>=500,MIN(I28:T28)<0.1*N(H28)),"CHECK OUTLIER MONTH",IF(AND(N(H28)>=50,LOOKUP(9.99E+307,I28:T28)=0),"LATEST = 0 · CHECK METER","OK"))))) -> OK
B29: 19 | C29: Nursery | D29: Support | H29: =IF(COUNT(E29:G29)=0,"",MEDIAN(E29:G29)) | I29: 48 | J29: 33 | K29: 43 | L29: 78 | M29: 204 | N29: 96 | O29: 176 | P29: 209 | U29: =IF(COUNT(I29:T29)=0,"",AVERAGE(I29:T29)) -> 110.875 | V29: =IF(COUNT(I29:T29)=0,"",SUM(I29:T29)) -> 887 | W29: =IF(OR(U29="",N(G29)=0),"",U29/G29-1) | X29: =IF(OR(U29="",N(H29)=0),"",U29/H29-1) | Y29: =COUNT(I29:T29) -> 8 | Z29: =IF(COUNT(I29:T29)=0,"NO 2026 DATA",IF(COUNT(I29:T29)<MATCH(9.99E+307,I29:T29)-MATCH(TRUE,INDEX(ISNUMBER(I29:T29),0),0)+1,"MISSING MONTH(S)",IF(AND(COUNT(E29:F29)=2,N(G29)>3*MAX(E29:F29)),"VERIFY AVG-2025 (>3× prior yrs)",IF(AND(N(H29)>=500,MIN(I29:T29)<0.1*N(H29)),"CHECK OUTLIER MONTH",IF(AND(N(H29)>=50,LOOKUP(9.99E+307,I29:T29)=0),"LATEST = 0 · CHECK METER","OK"))))) -> OK
B30: 20 | C30: Laundry | D30: Support | H30: =IF(COUNT(E30:G30)=0,"",MEDIAN(E30:G30)) | I30: 94 | J30: 98 | K30: 104 | L30: 15 | M30: 87 | N30: 68 | O30: 89 | P30: 135 | U30: =IF(COUNT(I30:T30)=0,"",AVERAGE(I30:T30)) -> 86.25 | V30: =IF(COUNT(I30:T30)=0,"",SUM(I30:T30)) -> 690 | W30: =IF(OR(U30="",N(G30)=0),"",U30/G30-1) | X30: =IF(OR(U30="",N(H30)=0),"",U30/H30-1) | Y30: =COUNT(I30:T30) -> 8 | Z30: =IF(COUNT(I30:T30)=0,"NO 2026 DATA",IF(COUNT(I30:T30)<MATCH(9.99E+307,I30:T30)-MATCH(TRUE,INDEX(ISNUMBER(I30:T30),0),0)+1,"MISSING MONTH(S)",IF(AND(COUNT(E30:F30)=2,N(G30)>3*MAX(E30:F30)),"VERIFY AVG-2025 (>3× prior yrs)",IF(AND(N(H30)>=500,MIN(I30:T30)<0.1*N(H30)),"CHECK OUTLIER MONTH",IF(AND(N(H30)>=50,LOOKUP(9.99E+307,I30:T30)=0),"LATEST = 0 · CHECK METER","OK"))))) -> OK
C31: Σ BUILDING SUB-METERS | E31: =IF(COUNT(E11:E30)=0,"",SUM(E11:E30)) -> 5466.7075 | F31: =IF(COUNT(F11:F30)=0,"",SUM(F11:F30)) -> 5670.125 | G31: =IF(COUNT(G11:G30)=0,"",SUM(G11:G30)) -> 35968.833 | H31: =IF(COUNT(H11:H30)=0,"",SUM(H11:H30)) -> 5904.5833 | I31: =IF(COUNT(I11:I30)=0,"",SUM(I11:I30)) -> 3511 | J31: =IF(COUNT(J11:J30)=0,"",SUM(J11:J30)) -> 3737 | K31: =IF(COUNT(K11:K30)=0,"",SUM(K11:K30)) -> 4736 | L31: =IF(COUNT(L11:L30)=0,"",SUM(L11:L30)) -> 4529 | ... T31: =IF(COUNT(T11:T30)=0,"",SUM(T11:T30)) | U31: =IF(COUNT(I31:T31)=0,"",AVERAGE(I31:T31)) -> 4585.875 | V31: =IF(COUNT(I31:T31)=0,"",SUM(I31:T31)) -> 36687 | W31: =IF(OR(U31="",N(G31)=0),"",U31/G31-1) -> -0.87250421 | X31: =IF(OR(U31="",N(H31)=0),"",U31/H31-1) -> -0.22333639
B32: B · PRIMARY USES (fed from borewells + STP outlet)
B33: 21 | C33: WTP (treated output) | D33: Primary use | E33: 5010.4167 | F33: 12262.25 | G33: 10719 | H33: =IF(COUNT(E33:G33)=0,"",MEDIAN(E33:G33)) -> 10719 | I33: 8770 | J33: 14597 | K33: 12927 | L33: 12096 | M33: 11615 | N33: 7361 | O33: 8310 | P33: 10986 | U33: =IF(COUNT(I33:T33)=0,"",AVERAGE(I33:T33)) -> 10832.75 | V33: =IF(COUNT(I33:T33)=0,"",SUM(I33:T33)) -> 86662 | W33: =IF(OR(U33="",N(G33)=0),"",U33/G33-1) -> 0.010611997 | X33: =IF(OR(U33="",N(H33)=0),"",U33/H33-1) -> 0.010611997 | Y33: =COUNT(I33:T33) -> 8 | Z33: =IF(COUNT(I33:T33)=0,"NO 2026 DATA",IF(COUNT(I33:T33)<MATCH(9.99E+307,I33:T33)-MATCH(TRUE,INDEX(ISNUMBER(I33:T33),0),0)+1,"MISSING MONTH(S)",IF(AND(COUNT(E33:F33)=2,N(G33)>3*MAX(E33:F33)),"VERIFY AVG-2025 (>3× prior yrs)",IF(AND(N(H33)>=500,MIN(I33:T33)<0.1*N(H33)),"CHECK OUTLIER MONTH",IF(AND(N(H33)>=50,LOOKUP(9.99E+307,I33:T33)=0),"LATEST = 0 · CHECK METER","OK"))))) -> OK
B34: 22 | C34: Drip irrigation | D34: Primary use | E34: 7038 | F34: 4009.4167 | G34: 6035.1667 | H34: =IF(COUNT(E34:G34)=0,"",MEDIAN(E34:G34)) -> 6035.1667 | I34: 5643 | J34: 6541 | K34: 6091 | L34: 7080 | M34: 7193 | N34: 3865 | O34: 1136 | P34: 2501 | U34: =IF(COUNT(I34:T34)=0,"",AVERAGE(I34:T34)) -> 5006.25 | V34: =IF(COUNT(I34:T34)=0,"",SUM(I34:T34)) -> 40050 | W34: =IF(OR(U34="",N(G34)=0),"",U34/G34-1) -> -0.17048687 | X34: =IF(OR(U34="",N(H34)=0),"",U34/H34-1) -> -0.17048687 | Y34: =COUNT(I34:T34) -> 8 | Z34: =IF(COUNT(I34:T34)=0,"NO 2026 DATA",IF(COUNT(I34:T34)<MATCH(9.99E+307,I34:T34)-MATCH(TRUE,INDEX(ISNUMBER(I34:T34),0),0)+1,"MISSING MONTH(S)",IF(AND(COUNT(E34:F34)=2,N(G34)>3*MAX(E34:F34)),"VERIFY AVG-2025 (>3× prior yrs)",IF(AND(N(H34)>=500,MIN(I34:T34)<0.1*N(H34)),"CHECK OUTLIER MONTH",IF(AND(N(H34)>=50,LOOKUP(9.99E+307,I34:T34)=0),"LATEST = 0 · CHECK METER","OK"))))) -> OK
B35: 23 | C35: Sports field | D35: Primary use | E35: 3818.8333 | F35: 4664.1667 | G35: 12882.75 | H35: =IF(COUNT(E35:G35)=0,"",MEDIAN(E35:G35)) -> 4664.1667 | I35: 3596 | J35: 0 | K35: 0 | L35: 0 | M35: 0 | O35: 0 | U35: =IF(COUNT(I35:T35)=0,"",AVERAGE(I35:T35)) -> 599.33333 | V35: =IF(COUNT(I35:T35)=0,"",SUM(I35:T35)) -> 3596 | W35: =IF(OR(U35="",N(G35)=0),"",U35/G35-1) -> -0.95347784 | X35: =IF(OR(U35="",N(H35)=0),"",U35/H35-1) -> -0.87150259 | Y35: =COUNT(I35:T35) -> 6 | Z35: =IF(COUNT(I35:T35)=0,"NO 2026 DATA",IF(COUNT(I35:T35)<MATCH(9.99E+307,I35:T35)-MATCH(TRUE,INDEX(ISNUMBER(I35:T35),0),0)+1,"MISSING MONTH(S)",IF(AND(COUNT(E35:F35)=2,N(G35)>3*MAX(E35:F35)),"VERIFY AVG-2025 (>3× prior yrs)",IF(AND(N(H35)>=500,MIN(I35:T35)<0.1*N(H35)),"CHECK OUTLIER MONTH",IF(AND(N(H35)>=50,LOOKUP(9.99E+307,I35:T35)=0),"LATEST = 0 · CHECK METER","OK"))))) -> MISSING MONTH(S)
C36: Σ PRIMARY USES | E36: =IF(COUNT(E33:E35)=0,"",SUM(E33:E35)) -> 15867.25 | F36: =IF(COUNT(F33:F35)=0,"",SUM(F33:F35)) -> 20935.833 | G36: =IF(COUNT(G33:G35)=0,"",SUM(G33:G35)) -> 29636.917 | H36: =IF(COUNT(H33:H35)=0,"",SUM(H33:H35)) -> 21418.333 | I36: =IF(COUNT(I33:I35)=0,"",SUM(I33:I35)) -> 18009 | J36: =IF(COUNT(J33:J35)=0,"",SUM(J33:J35)) -> 21138 | K36: =IF(COUNT(K33:K35)=0,"",SUM(K33:K35)) -> 19018 | L36: =IF(COUNT(L33:L35)=0,"",SUM(L33:L35)) -> 19176 | ... T36: =IF(COUNT(T33:T35)=0,"",SUM(T33:T35)) | U36: =IF(COUNT(I36:T36)=0,"",AVERAGE(I36:T36)) -> 16288.5 | V36: =IF(COUNT(I36:T36)=0,"",SUM(I36:T36)) -> 130308 | W36: =IF(OR(U36="",N(G36)=0),"",U36/G36-1) -> -0.45039829 | X36: =IF(OR(U36="",N(H36)=0),"",U36/H36-1) -> -0.23950665
B37: C · SOURCES (campus inlet)
B38: 24 | C38: Borewells | D38: Source | E38: 11410.118 | F38: 17298.033 | G38: 29581.061 | H38: =IF(COUNT(E38:G38)=0,"",MEDIAN(E38:G38)) -> 17298.033 | I38: 15002 | J38: 19302.67 | K38: 17647.45 | L38: 18490.49 | M38: 21759.4 | N38: 11528.59 | O38: 15618.59 | P38: 11995 | U38: =IF(COUNT(I38:T38)=0,"",AVERAGE(I38:T38)) -> 16418.024 | V38: =IF(COUNT(I38:T38)=0,"",SUM(I38:T38)) -> 131344.19 | W38: =IF(OR(U38="",N(G38)=0),"",U38/G38-1) -> -0.44498191 | X38: =IF(OR(U38="",N(H38)=0),"",U38/H38-1) -> -0.050873389 | Y38: =COUNT(I38:T38) -> 8 | Z38: =IF(COUNT(I38:T38)=0,"NO 2026 DATA",IF(COUNT(I38:T38)<MATCH(9.99E+307,I38:T38)-MATCH(TRUE,INDEX(ISNUMBER(I38:T38),0),0)+1,"MISSING MONTH(S)",IF(AND(COUNT(E38:F38)=2,N(G38)>3*MAX(E38:F38)),"VERIFY AVG-2025 (>3× prior yrs)",IF(AND(N(H38)>=500,MIN(I38:T38)<0.1*N(H38)),"CHECK OUTLIER MONTH",IF(AND(N(H38)>=50,LOOKUP(9.99E+307,I38:T38)=0),"LATEST = 0 · CHECK METER","OK"))))) -> OK
B39: 25 | C39: STP outlet (recycled) | D39: Source | E39: 7230.2692 | F39: 3584 | G39: 4534.8333 | H39: =IF(COUNT(E39:G39)=0,"",MEDIAN(E39:G39)) -> 4534.8333 | I39: 3596 | J39: 5654 | K39: 4885 | L39: 3764 | M39: 1496 | N39: 1929 | O39: 2303 | P39: 2683 | U39: =IF(COUNT(I39:T39)=0,"",AVERAGE(I39:T39)) -> 3288.75 | V39: =IF(COUNT(I39:T39)=0,"",SUM(I39:T39)) -> 26310 | W39: =IF(OR(U39="",N(G39)=0),"",U39/G39-1) -> -0.2747804 | X39: =IF(OR(U39="",N(H39)=0),"",U39/H39-1) -> -0.2747804 | Y39: =COUNT(I39:T39) -> 8 | Z39: =IF(COUNT(I39:T39)=0,"NO 2026 DATA",IF(COUNT(I39:T39)<MATCH(9.99E+307,I39:T39)-MATCH(TRUE,INDEX(ISNUMBER(I39:T39),0),0)+1,"MISSING MONTH(S)",IF(AND(COUNT(E39:F39)=2,N(G39)>3*MAX(E39:F39)),"VERIFY AVG-2025 (>3× prior yrs)",IF(AND(N(H39)>=500,MIN(I39:T39)<0.1*N(H39)),"CHECK OUTLIER MONTH",IF(AND(N(H39)>=50,LOOKUP(9.99E+307,I39:T39)=0),"LATEST = 0 · CHECK METER","OK"))))) -> OK
