Workbook

Sheet FM_Dashboard
A1: AKESI | B1: AKESI SCHOOLS | FACILITY MANAGEMENT MIS DASHBOARD
A2: SCHOOLS · FM | B2: ="Calendar 2026 • live MIS data Jan-26 to "&MIS_Calc!$B$7&" • Electricity · Solar · Water · Repairs · Generators · AMC · Water tests • 10 schools • "&TEXT(MIS_Calc!$N$92,"#,##0")&" pupils (2026 average)" -> Calendar 2026 • live MIS data Jan-26 to Sep-26 • Electricity · Solar · Water · Repairs · Generators · AMC · Water tests • 10 schools • 6,788 pupils (2026 average)
B4: MONTH | H4: SCHOOL | P4: ="Showing: "&MIS_Calc!$B$3&" • School: "&MIS_Calc!$B$4&" • Latest data "&MIS_Calc!$B$7&" (all 10 schools reported to "&MIS_Calc!$B$9&")" -> Showing: Sep-26 • School: All Schools • Latest data Sep-26 (all 10 schools reported to Jul-26)
A5: ▶ FM Dashboard | B5: 📅 Select ▸ | D5: Sep-26 | H5: 🏫 Drill ▸ | J5: All Schools | P5: Pick a month (or 2026 YTD) and a school from the yellow drop-downs. Cards, charts and the scorecard follow the selection. 'vs prev month' compares with the month before; YTD averages use only months with data.
A7: Electricity | B7: ⚡ GRID ENERGY (kWh) | F7: ₹ ENERGY BILL (₹ Lakh) | J7: ☀ SOLAR GENERATION (kWh) | N7: 💧 WATER CONSUMED (kL) | R7: 🚰 WATER PER PUPIL (L / pupil / day) | V7: 🎓 ENERGY PER PUPIL (kWh / pupil / month)
B8: =IF(MIS_Calc!$E$292="","NO DATA",MIS_Calc!$E$292) -> 20775 | F8: =IF(MIS_Calc!$E$293="","NO DATA",MIS_Calc!$E$293/100000) -> 2.56238 | J8: =IF(MIS_Calc!$E$294="","NO DATA",MIS_Calc!$E$294) -> 7494 | N8: =IF(MIS_Calc!$E$295="","NO DATA",MIS_Calc!$E$295/1000) -> 3046.376 | R8: =IF(MIS_Calc!$E$304="","NO DATA",MIS_Calc!$E$304) -> 15.931262 | V8: =IF(MIS_Calc!$E$306="","NO DATA",MIS_Calc!$E$306) -> 6.4618974
A9: Water | B9: =IF(MIS_Calc!$E$292="","no data for this selection",IF(MIS_Calc!$B$5=13,"Avg/month "&TEXT(MIS_Calc!$H$292,"#,##0")&" • "&MIS_Calc!$K$292&" months logged",IF(MIS_Calc!$I$292="","vs prev month –","vs prev month "&TEXT(MIS_Calc!$I$292,"+0%;-0%;0%"))&IF(MIS_Calc!$B$6=11," • "&MIS_Calc!$K$292&" of 10 schools reported",""))) -> vs prev month -65% • 5 of 10 schools reported | F9: =IF(MIS_Calc!$E$293="","no data for this selection",IF(MIS_Calc!$E$305="","","₹"&TEXT(MIS_Calc!$E$305,"0.00")&"/kWh • ")&IF(MIS_Calc!$B$5=13,"Avg/month ₹"&TEXT(MIS_Calc!$H$293/100000,"0.0")&" L",IF(MIS_Calc!$I$293="","vs prev month –","vs prev month "&TEXT(MIS_Calc!$I$293,"+0%;-0%;0%")))) -> ₹12.33/kWh • vs prev month -63% | J9: =IF(MIS_Calc!$E$294="","no data for this selection",IF(MIS_Calc!$B$5=13,"Avg/month "&TEXT(MIS_Calc!$H$294,"#,##0"),IF(MIS_Calc!$I$294="","vs prev month –","vs prev month "&TEXT(MIS_Calc!$I$294,"+0%;-0%;0%")))&IF(MIS_Calc!$B$6=11," • sites: AKSM, AKSC, AKHH","")) -> vs prev month -75% • sites: AKSM, AKSC, AKHH | N9: =IF(MIS_Calc!$E$295="","no data for this selection",IF(MIS_Calc!$B$5=13,"Avg/month "&TEXT(MIS_Calc!$H$295/1000,"#,##0")&" • "&MIS_Calc!$K$295&" months logged",IF(MIS_Calc!$I$295="","vs prev month –","vs prev month "&TEXT(MIS_Calc!$I$295,"+0%;-0%;0%"))&IF(MIS_Calc!$B$6=11," • "&MIS_Calc!$K$295&" of 10 schools reported",""))) -> vs prev month -9% • 8 of 10 schools reported | R9: =IF(MIS_Calc!$E$304="","no data for this selection","Pupils "&TEXT(MIS_Calc!$E$296,"#,##0")&" • 2026 YTD "&IF(MIS_Calc!$G$304="","–",TEXT(MIS_Calc!$G$304,"0.0"))&" L") -> Pupils 6,374 • 2026 YTD 14.5 L | V9: =IF(MIS_Calc!$E$306="","no data for this selection","2026 YTD "&IF(MIS_Calc!$G$306="","–",TEXT(MIS_Calc!$G$306,"0.0"))&" • bill ₹"&IFERROR(TEXT(MIS_Calc!$E$293/MIS_Calc!$E$298,"#,##0"),"–")&" per pupil") -> 2026 YTD 6.9 • bill ₹80 per pupil
A11: Repairs | B11: 🔧 REPAIR TICKETS | F11: ₹ REPAIR SPEND (₹ '000) | J11: ⛽ GENERATOR DIESEL (L) | N11: 📄 AMC CONTRACTS ACTIVE | R11: 🧪 WATER TESTS ABOVE LIMIT | V11: 📊 DATA COVERAGE
B12: =IF(MIS_Calc!$E$299="","NO DATA",MIS_Calc!$E$299) -> 96 | F12: =IF(MIS_Calc!$E$300="","NO DATA",MIS_Calc!$E$300/1000) -> 75.728 | J12: =IF(MIS_Calc!$E$302="","NO DATA",MIS_Calc!$E$302) -> 60 | N12: =MIS_Calc!$C$367+MIS_Calc!$C$368+MIS_Calc!$C$369 -> 16 | R12: =MIS_Calc!$C$378 -> 94 | V12: =IF(MIS_Calc!$E$307="","NO DATA",MIS_Calc!$E$307) -> 0.65
A13: Generators | B13: =IF(MIS_Calc!$E$299="","no data for this selection",IF(MIS_Calc!$B$5=13,"Avg/month "&TEXT(MIS_Calc!$H$299,"#,##0"),IF(MIS_Calc!$I$299="","vs prev month –","vs prev month "&TEXT(MIS_Calc!$I$299,"+0%;-0%;0%")))&IF(OR(MIS_Calc!$B$6=6,MIS_Calc!$B$6=7)," • DJHSH PRI + HS combined","")) -> vs prev month -26% | F13: =IF(MIS_Calc!$E$300="","no data for this selection",IF(MIS_Calc!$B$5=13,"Avg/month ₹"&TEXT(MIS_Calc!$H$300/1000,"#,##0.0")&"k",IF(MIS_Calc!$I$300="","vs prev month –","vs prev month "&TEXT(MIS_Calc!$I$300,"+0%;-0%;0%")))&" • 2026 YTD ₹"&TEXT(MIS_Calc!$G$300/100000,"0.0")&" L") -> vs prev month -57% • 2026 YTD ₹16.0 L | J13: =IF(MIS_Calc!$E$302="","no generator log for this selection","Units "&IF(MIS_Calc!$E$301="","–",TEXT(MIS_Calc!$E$301,"#,##0"))&" kWh • run "&IF(MIS_Calc!$E$303="","–",TEXT(MIS_Calc!$E$303,"0.0"))&" h"&IF(MIS_Calc!$B$6=11," • 3 generators","")) -> Units 149 kWh • run 29.1 h • 3 generators | N13: ="Expired "&MIS_Calc!$C$370&" • due ≤90 d "&(MIS_Calc!$C$368+MIS_Calc!$C$369)&" • incomplete "&MIS_Calc!$C$371&" of "&MIS_Calc!$C$373 -> Expired 12 • due ≤90 d 4 • incomplete 42 of 71 | R13: ="of "&MIS_Calc!$C$380&" results • drinking / RO points "&MIS_Calc!$C$379 -> of 532 results • drinking / RO points 4 | V13: =IF(MIS_Calc!$B$5=13,"Jan-26 to "&MIS_Calc!$B$7&" • electricity + water","Electricity "&MIS_Calc!$F$307&"/10 • water "&MIS_Calc!$G$307&"/10 schools") -> Electricity 5/10 • water 8/10 schools
A15: Water Tests
A17: AMC Log
A19: Check List
A21: Config
A23: Audit Control
A25: KPI Engine
A27: Summary
A29: Calc engine
B72: 🏫 SCHOOL SCORECARD (month filter applies • selected school highlighted • DJHSH repairs are logged for PRI + HS together • AMC expired is as of the audit date in CONFIG)
B73: School | F73: Grid kWh | H73: Bill ₹ | J73: ₹ / kWh | L73: kWh / pupil / month | N73: Water kL | P73: L / pupil / day | R73: Pupils | T73: Repair tickets | V73: Repair spend ₹ | X73: AMC expired
B74: =MIS_Calc!$A$387 -> DJHSM | F74: =IF(MIS_Calc!$B$387="","–",MIS_Calc!$B$387) -> – | H74: =IF(MIS_Calc!$C$387="","–",MIS_Calc!$C$387) -> – | J74: =IF(MIS_Calc!$D$387="","–",MIS_Calc!$D$387) -> – | L74: =IF(MIS_Calc!$E$387="","–",MIS_Calc!$E$387) -> – | N74: =IF(MIS_Calc!$F$387="","–",MIS_Calc!$F$387) -> 42.3 | P74: =IF(MIS_Calc!$G$387="","–",MIS_Calc!$G$387) -> 1.1681856 | R74: =IF(MIS_Calc!$H$387="","–",MIS_Calc!$H$387) -> 1207 | T74: =IF(MIS_Calc!$I$387="","–",MIS_Calc!$I$387) -> – | V74: =IF(MIS_Calc!$J$387="","–",MIS_Calc!$J$387) -> – | X74: =IF(MIS_Calc!$K$387="","–",MIS_Calc!$K$387) -> 1
B75: =MIS_Calc!$A$388 -> DJG | F75: =IF(MIS_Calc!$B$388="","–",MIS_Calc!$B$388) -> 3820 | H75: =IF(MIS_Calc!$C$388="","–",MIS_Calc!$C$388) -> 43607 | J75: =IF(MIS_Calc!$D$388="","–",MIS_Calc!$D$388) -> 11.415445 | L75: =IF(MIS_Calc!$E$388="","–",MIS_Calc!$E$388) -> 3.745098 | N75: =IF(MIS_Calc!$F$388="","–",MIS_Calc!$F$388) -> 13.436 | P75: =IF(MIS_Calc!$G$388="","–",MIS_Calc!$G$388) -> 0.43908497 | R75: =IF(MIS_Calc!$H$388="","–",MIS_Calc!$H$388) -> 1020 | T75: =IF(MIS_Calc!$I$388="","–",MIS_Calc!$I$388) -> 3 | V75: =IF(MIS_Calc!$J$388="","–",MIS_Calc!$J$388) -> 37240 | X75: =IF(MIS_Calc!$K$388="","–",MIS_Calc!$K$388) -> 0
B76: =MIS_Calc!$A$389 -> AKSM | F76: =IF(MIS_Calc!$B$389="","–",MIS_Calc!$B$389) -> – | H76: =IF(MIS_Calc!$C$389="","–",MIS_Calc!$C$389) -> – | J76: =IF(MIS_Calc!$D$389="","–",MIS_Calc!$D$389) -> – | L76: =IF(MIS_Calc!$E$389="","–",MIS_Calc!$E$389) -> – | N76: =IF(MIS_Calc!$F$389="","–",MIS_Calc!$F$389) -> – | P76: =IF(MIS_Calc!$G$389="","–",MIS_Calc!$G$389) -> – | R76: =IF(MIS_Calc!$H$389="","–",MIS_Calc!$H$389) -> – | T76: =IF(MIS_Calc!$I$389="","–",MIS_Calc!$I$389) -> – | V76: =IF(MIS_Calc!$J$389="","–",MIS_Calc!$J$389) -> – | X76: =IF(MIS_Calc!$K$389="","–",MIS_Calc!$K$389) -> 2
B77: =MIS_Calc!$A$390 -> AKSS | F77: =IF(MIS_Calc!$B$390="","–",MIS_Calc!$B$390) -> – | H77: =IF(MIS_Calc!$C$390="","–",MIS_Calc!$C$390) -> – | J77: =IF(MIS_Calc!$D$390="","–",MIS_Calc!$D$390) -> – | L77: =IF(MIS_Calc!$E$390="","–",MIS_Calc!$E$390) -> – | N77: =IF(MIS_Calc!$F$390="","–",MIS_Calc!$F$390) -> 27.9 | P77: =IF(MIS_Calc!$G$390="","–",MIS_Calc!$G$390) -> 1.754717 | R77: =IF(MIS_Calc!$H$390="","–",MIS_Calc!$H$390) -> 530 | T77: =IF(MIS_Calc!$I$390="","–",MIS_Calc!$I$390) -> 3 | V77: =IF(MIS_Calc!$J$390="","–",MIS_Calc!$J$390) -> 6020 | X77: =IF(MIS_Calc!$K$390="","–",MIS_Calc!$K$390) -> 0
B78: =MIS_Calc!$A$391 -> AKSC | F78: =IF(MIS_Calc!$B$391="","–",MIS_Calc!$B$391) -> – | H78: =IF(MIS_Calc!$C$391="","–",MIS_Calc!$C$391) -> – | J78: =IF(MIS_Calc!$D$391="","–",MIS_Calc!$D$391) -> – | L78: =IF(MIS_Calc!$E$391="","–",MIS_Calc!$E$391) -> – | N78: =IF(MIS_Calc!$F$391="","–",MIS_Calc!$F$391) -> – | P78: =IF(MIS_Calc!$G$391="","–",MIS_Calc!$G$391) -> – | R78: =IF(MIS_Calc!$H$391="","–",MIS_Calc!$H$391) -> – | T78: =IF(MIS_Calc!$I$391="","–",MIS_Calc!$I$391) -> – | V78: =IF(MIS_Calc!$J$391="","–",MIS_Calc!$J$391) -> – | X78: =IF(MIS_Calc!$K$391="","–",MIS_Calc!$K$391) -> 0
B79: =MIS_Calc!$A$392 -> DJHSH (PRI) | F79: =IF(MIS_Calc!$B$392="","–",MIS_Calc!$B$392) -> 1187 | H79: =IF(MIS_Calc!$C$392="","–",MIS_Calc!$C$392) -> 13538 | J79: =IF(MIS_Calc!$D$392="","–",MIS_Calc!$D$392) -> 11.405223 | L79: =IF(MIS_Calc!$E$392="","–",MIS_Calc!$E$392) -> 4.1215278 | N79: =IF(MIS_Calc!$F$392="","–",MIS_Calc!$F$392) -> 78.11 | P79: =IF(MIS_Calc!$G$392="","–",MIS_Calc!$G$392) -> 9.0405093 | R79: =IF(MIS_Calc!$H$392="","–",MIS_Calc!$H$392) -> 288 | T79: =IF(MIS_Calc!$I$392="","–",MIS_Calc!$I$392) -> 4 | V79: =IF(MIS_Calc!$J$392="","–",MIS_Calc!$J$392) -> 9588 | X79: =IF(MIS_Calc!$K$392="","–",MIS_Calc!$K$392) -> 2
B80: =MIS_Calc!$A$393 -> DJHSH (HS) | F80: =IF(MIS_Calc!$B$393="","–",MIS_Calc!$B$393) -> 3427 | H80: =IF(MIS_Calc!$C$393="","–",MIS_Calc!$C$393) -> 38841 | J80: =IF(MIS_Calc!$D$393="","–",MIS_Calc!$D$393) -> 11.33382 | L80: =IF(MIS_Calc!$E$393="","–",MIS_Calc!$E$393) -> 5.7116667 | N80: =IF(MIS_Calc!$F$393="","–",MIS_Calc!$F$393) -> 141.3 | P80: =IF(MIS_Calc!$G$393="","–",MIS_Calc!$G$393) -> 7.85 | R80: =IF(MIS_Calc!$H$393="","–",MIS_Calc!$H$393) -> 600 | T80: =IF(MIS_Calc!$I$393="","–",MIS_Calc!$I$393) -> with PRI | V80: =IF(MIS_Calc!$J$393="","–",MIS_Calc!$J$393) -> with PRI | X80: =IF(MIS_Calc!$K$393="","–",MIS_Calc!$K$393) -> 2
B81: =MIS_Calc!$A$394 -> PJHSW | F81: =IF(MIS_Calc!$B$394="","–",MIS_Calc!$B$394) -> – | H81: =IF(MIS_Calc!$C$394="","–",MIS_Calc!$C$394) -> – | J81: =IF(MIS_Calc!$D$394="","–",MIS_Calc!$D$394) -> – | L81: =IF(MIS_Calc!$E$394="","–",MIS_Calc!$E$394) -> – | N81: =IF(MIS_Calc!$F$394="","–",MIS_Calc!$F$394) -> 699 | P81: =IF(MIS_Calc!$G$394="","–",MIS_Calc!$G$394) -> 16.385373 | R81: =IF(MIS_Calc!$H$394="","–",MIS_Calc!$H$394) -> 1422 | T81: =IF(MIS_Calc!$I$394="","–",MIS_Calc!$I$394) -> 1 | V81: =IF(MIS_Calc!$J$394="","–",MIS_Calc!$J$394) -> 2730 | X81: =IF(MIS_Calc!$K$394="","–",MIS_Calc!$K$394) -> 2
B82: =MIS_Calc!$A$395 -> LSHSA | F82: =IF(MIS_Calc!$B$395="","–",MIS_Calc!$B$395) -> 3089 | H82: =IF(MIS_Calc!$C$395="","–",MIS_Calc!$C$395) -> 37962 | J82: =IF(MIS_Calc!$D$395="","–",MIS_Calc!$D$395) -> 12.289414 | L82: =IF(MIS_Calc!$E$395="","–",MIS_Calc!$E$395) -> 2.6767764 | N82: =IF(MIS_Calc!$F$395="","–",MIS_Calc!$F$395) -> 456.33 | P82: =IF(MIS_Calc!$G$395="","–",MIS_Calc!$G$395) -> 13.181109 | R82: =IF(MIS_Calc!$H$395="","–",MIS_Calc!$H$395) -> 1154 | T82: =IF(MIS_Calc!$I$395="","–",MIS_Calc!$I$395) -> 9 | V82: =IF(MIS_Calc!$J$395="","–",MIS_Calc!$J$395) -> 20150 | X82: =IF(MIS_Calc!$K$395="","–",MIS_Calc!$K$395) -> 2
B83: =MIS_Calc!$A$396 -> AKHH | F83: =IF(MIS_Calc!$B$396="","–",MIS_Calc!$B$396) -> 9252 | H83: =IF(MIS_Calc!$C$396="","–",MIS_Calc!$C$396) -> 122290 | J83: =IF(MIS_Calc!$D$396="","–",MIS_Calc!$D$396) -> 13.217683 | L83: =IF(MIS_Calc!$E$396="","–",MIS_Calc!$E$396) -> 60.470588 | N83: =IF(MIS_Calc!$F$396="","–",MIS_Calc!$F$396) -> 1588 | P83: =IF(MIS_Calc!$G$396="","–",MIS_Calc!$G$396) -> 345.9695 | R83: =IF(MIS_Calc!$H$396="","–",MIS_Calc!$H$396) -> 153 | T83: =IF(MIS_Calc!$I$396="","–",MIS_Calc!$I$396) -> 76 | V83: =IF(MIS_Calc!$J$396="","–",MIS_Calc!$J$396) -> – | X83: =IF(MIS_Calc!$K$396="","–",MIS_Calc!$K$396) -> 1
B84: ALL SCHOOLS | F84: =IF(MIS_Calc!$B$397="","–",MIS_Calc!$B$397) -> 20775 | H84: =IF(MIS_Calc!$C$397="","–",MIS_Calc!$C$397) -> 256238 | J84: =IF(MIS_Calc!$D$397="","–",MIS_Calc!$D$397) -> 12.333959 | L84: =IF(MIS_Calc!$E$397="","–",MIS_Calc!$E$397) -> 6.4618974 | N84: =IF(MIS_Calc!$F$397="","–",MIS_Calc!$F$397) -> 3046.376 | P84: =IF(MIS_Calc!$G$397="","–",MIS_Calc!$G$397) -> 15.931262 | R84: =IF(MIS_Calc!$H$397="","–",MIS_Calc!$H$397) -> 6374 | T84: =IF(MIS_Calc!$I$397="","–",MIS_Calc!$I$397) -> 96 | V84: =IF(MIS_Calc!$J$397="","–",MIS_Calc!$J$397) -> 75728 | X84: =IF(MIS_Calc!$K$397="","–",MIS_Calc!$K$397) -> 12
B86: 🚨 WATCHLIST (live, follows the filters) | N86: 🔎 DATA-QUALITY FINDINGS IN SOURCE SHEETS (please verify)
B87: Grid energy vs 2026 monthly average | J87: =MIS_Calc!$J$292 -> -0.56370853 | L87: =IF(MIS_Calc!$J$292="","–",IF(MIS_Calc!$J$292>MIS_Calc!$B$14,"▲ Watch","✔ OK")) -> ✔ OK | N87: 1. Electrical Consmp. C34:E34 (AKSC solar export, Jan–Mar) hold a stray array formula that adds other schools' consumption (22,336 / 25,824 / 24,262). The dashboard uses the solar generation rows only.
B88: Water consumed vs 2026 monthly average | J88: =MIS_Calc!$J$295 -> -0.0013954325 | L88: =IF(MIS_Calc!$J$295="","–",IF(MIS_Calc!$J$295>MIS_Calc!$B$14,"▲ Watch","✔ OK")) -> ✔ OK | N88: 2. AKSC solar yield (Electrical Consmp. row 35) divides by the AKSM capacity of 20 kWp, giving 14–24 kWh/kWp/day from April. Enter AKSC's installed kWp in CONFIG and point row 35 at it.
B89: Energy unit cost (₹/kWh) vs 2026 YTD | J89: =MIS_Calc!$J$305 -> 0.027170926 | L89: =IF(MIS_Calc!$J$305="","–",IF(MIS_Calc!$J$305>MIS_Calc!$B$14,"▲ Watch","✔ OK")) -> ✔ OK | N89: 3. AKHH electricity cost: March shows ₹12,040 for 8,431 kWh (₹1.43/kWh) and May ₹24.16/kWh against about ₹12–13 in other months. AKSC shows ₹0.85–1.84/kWh for Jun–Aug.
B90: Repair spend vs 2026 monthly average | J90: =MIS_Calc!$J$300 -> -0.59635294 | L90: =IF(MIS_Calc!$J$300="","–",IF(MIS_Calc!$J$300>MIS_Calc!$B$14,"▲ Watch","✔ OK")) -> ✔ OK | N90: 4. Water Consmp.: May pupil counts are 10–41 for six schools (vacation headcount), so May litres per pupil per day reads 10–172. The YTD figure uses pupil-days and is not distorted.
B91: Schools yet to report electricity for the latest month | J91: =MIS_Calc!$E$308 -> 5 | L91: =IF(MIS_Calc!$E$308="","–",IF(MIS_Calc!$E$308>0,"▲ Act","✔ OK")) -> ▲ Act | N91: 5. Water per pupil is about 0.5 L/day at DJG and 1.2–1.7 L/day at DJHSM but 185–407 L/day at AKHH — check meter units and whether AKHH is residential.
B92: Schools yet to report water for the latest month | J92: =MIS_Calc!$F$308 -> 2 | L92: =IF(MIS_Calc!$F$308="","–",IF(MIS_Calc!$F$308>0,"▲ Act","✔ OK")) -> ▲ Act | N92: 6. September is part-reported: electricity for 5 of 10 schools and water for 8 of 10. September totals are therefore partial.
B93: AMC contracts expired | J93: =MIS_Calc!$C$370 -> 12 | L93: =IF(MIS_Calc!$C$370="","–",IF(MIS_Calc!$C$370>0,"▲ Act","✔ OK")) -> ▲ Act | N93: 7. AMC-LOG: 42 of 71 records have no start or expiry date (INCOMPLETE), 12 are expired and 1 has a date error, as of the audit date in CONFIG!B8.
B94: AMC contracts expiring within 30 days | J94: =MIS_Calc!$C$368 -> 1 | L94: =IF(MIS_Calc!$C$368="","–",IF(MIS_Calc!$C$368>0,"▲ Act","✔ OK")) -> ▲ Act | N94: 8. REPAIRS: AKHH logs ticket counts but no spend, so its spend reads '–'. DJHSH repairs are not split between PRI and HS. Oct–Dec blocks have six rows and no category labels (seven categories are used Jan–Sep).
...

Sheet Electrical Consmp.
A1: AKESI Power Charges with Consumed Units - 2026
A3: School / Month | C3: January | D3: February | E3: March | F3: April | G3: May | H3: June | I3: July | J3: August | K3: September | L3: October | M3: November | N3: December
A4: DJHSM | B4: Elec. Cons. (Kwhr) | C4: 11200 | D4: 12400 | E4: 12000 | F4: 14600 | G4: 9000 | H4: 16800 | I4: 15000 | J4: 14800 | O4: =C4+D4+E4+F4+G4+H4+I4+J4+K4+L4+M4+N4 -> 105800
B5: Cost | C5: 138780 | D5: 169170 | E5: 187880 | F5: 215190 | G5: 160300 | H5: 248550 | I5: 231650 | J5: 242730 | O5: =C5+D5+E5+F5+G5+H5+I5+J5+K5+L5+M5+N5 -> 1594250
B6: MD (500)-1 | C6: 200 | D6: 200 | E6: 200 | F6: 200 | G6: 200 | H6: 200 | I6: 200 | J6: 200
B7: Solar Export | C7: 0 | D7: 0 | E7: 0 | F7: 0 | G7: 0 | H7: 0 | I7: 0 | J7: 0
B8: Cost | C8: 0 | D8: 0 | E8: 0 | F8: 0 | G8: 0 | H8: 0 | I8: 0 | J8: 0
B9: Qtly | C9: =C4+D4+E4+C7+D7+E7 -> 35600 | F9: =F4+G4+H4+F7+G7+H7 -> 40400 | I9: =I4+J4+K4+I7+J7+K7 -> 29800 | L9: =L4+M4+N4+L7+M7+N7 -> 0
A10: DJG | B10: Elec. Cons. (Kwhr) | C10: =694+240+1346 -> 2280 | D10: =243+927+1557 -> 2727 | E10: =1009+242+1803 -> 3054 | F10: =1824+279+1231 -> 3334 | G10: =802+208+1354 -> 2364 | H10: =663+255+1401 -> 2319 | I10: =1352+319+1989 -> 3660 | J10: =323+2252+1309 -> 3884 | K10: =1243+2259+318 -> 3820 | O10: =C10+D10+E10+F10+G10+H10+I10+J10+K10+L10+M10+N10 -> 27442
B11: Cost | C11: =7911+3097+13763 -> 24771 | D11: =3133+10381+15579 -> 29093 | E11: =14855+10114+738 -> 25707 | F11: =13169+3396+17574 -> 34139 | G11: =8439+2597+13152 -> 24188 | H11: =7174+3091+13780 -> 24045 | I11: =14645+3893+20351 -> 38889 | J11: =3968+23200+14415 -> 41583 | K11: =14591+24872+4144 -> 43607 | O11: =C11+D11+E11+F11+G11+H11+I11+J11+K11+L11+M11+N11 -> 286022
B12: MD-3
B13: Solar Export | C13: 0 | D13: 0 | E13: 0 | F13: 0 | G13: 0 | H13: 0 | I13: 0 | J13: 0 | K13: 0
B14: Cost | C14: 0 | D14: 0 | E14: 0 | F14: 0 | G14: 0 | H14: 0 | I14: 0 | J14: 0 | K14: 0
B15: Qtly | C15: =C10+D10+E10+C13+D13+E13 -> 8061 | F15: =F10+G10+H10+F13+G13+H13 -> 8017 | I15: =I10+J10+K10+I13+J13+K13 -> 11364 | L15: =L10+M10+N10+L13+M13+N13 -> 0
A16: AKSM | B16: Elec. Cons. (Kwhr) | C16: =964+412 -> 1376 | D16: =565+455 -> 1020 | E16: =753+558 -> 1311 | F16: =1578+600 -> 2178 | G16: =32+306 -> 338 | H16: =1425+975 -> 2400 | I16: =1112+2484 -> 3596 | J16: =2707+795 -> 3502 | O16: =C16+D16+E16+F16+G16+H16+I16+J16+K16+L16+M16+N16 -> 15721
B17: Cost | C17: =3616+15985 -> 19601 | D17: =4777+12244 -> 17021 | E17: =17465+4724 -> 22189 | F17: =22461+5043 -> 27504 | G17: =7819+2405 -> 10224 | H17: =14156+7900 -> 22056 | I17: =8932+35217 -> 44149 | J17: =7055+39110 -> 46165 | O17: =C17+D17+E17+F17+G17+H17+I17+J17+K17+L17+M17+N17 -> 208909
B18: MD (74)-2 | C18: =17+55 -> 72 | D18: =17+55 -> 72 | E18: =17+55 -> 72 | F18: =17+55 -> 72 | G18: =17+55 -> 72 | H18: =17+55 -> 72 | I18: =17+55 -> 72 | J18: =17+55 -> 72
B19: Solar Gen(Kwhr) Import | C19: 1829 | D19: 2464 | E19: 2982 | F19: 2965 | G19: 2826 | H19: 2617 | I19: 3348 | J19: 3594 | O19: =SUM(C19:N19) -> 22625
B20: Solar Gen(Kwhr) Export | C20: 647 | D20: 874 | E20: 2143 | F20: 1578 | G20: 909 | H20: 1192 | I20: 864 | J20: 508
B21: Kwhr/Kwp/day | C21: =IF(C19="","",(C19/CONFIG!$B$6)/CONFIG!$B$3) -> 2.95 | D21: =IF(D19="","",(D19/CONFIG!$B$6)/CONFIG!$C$3) -> 4.4 | E21: =IF(E19="","",(E19/CONFIG!$B$6)/CONFIG!$D$3) -> 4.8096774 | F21: =IF(F19="","",(F19/CONFIG!$B$6)/CONFIG!$E$3) -> 4.9416667 | G21: =IF(G19="","",(G19/CONFIG!$B$6)/CONFIG!$F$3) -> 4.5580645 | H21: =IF(H19="","",(H19/CONFIG!$B$6)/CONFIG!$G$3) -> 4.3616667 | I21: =IF(I19="","",(I19/CONFIG!$B$6)/CONFIG!$H$3) -> 5.4 | J21: =IF(J19="","",(J19/CONFIG!$B$6)/CONFIG!$I$3) -> 5.7967742 | K21: =IF(K19="","",(K19/CONFIG!$B$6)/CONFIG!$J$3) | L21: =IF(L19="","",(L19/CONFIG!$B$6)/CONFIG!$K$3) | M21: =IF(M19="","",(M19/CONFIG!$B$6)/CONFIG!$L$3) | N21: =IF(N19="","",(N19/CONFIG!$B$6)/CONFIG!$M$3)
B22: Qtly | C22: =C16+D16+E16+C20+D20+E20 -> 7371 | F22: =F16+G16+H16+F20+G20+H20 -> 8595 | I22: =I16+J16+K16+I20+J20+K20 -> 8470 | L22: =L16+M16+N16+L20+M20+N20 -> 0
A23: AKSS | B23: Elec. Cons. (Kwhr) | C23: 2261 | D23: 2111 | E23: 2872 | F23: 4747 | G23: 5189 | H23: 7265 | I23: 5844 | J23: 4860 | O23: =C23+D23+E23+F23+G23+H23+I23+J23+K23+L23+M23+N23 -> 35149
B24: Cost | C24: 16587 | D24: 15540 | E24: 20966 | F24: 29893 | G24: 32910 | H24: 50078 | I24: 40421 | J24: 33765 | O24: =C24+D24+E24+F24+G24+H24+I24+J24+K24+L24+M24+N24 -> 240160
B25: MD-2 | G25: 19.5
B26: Solar Gen(Kwhr) Import | C26: 0 | D26: 0 | E26: 0 | F26: 0 | G26: 0 | H26: 0 | I26: 0 | J26: 0
B27: Solar Gen(Kwhr) Export | C27: 0 | D27: 0 | E27: 0 | F27: 0 | G27: 0 | H27: 0 | I27: 0 | J27: 0
B28: Cost | C28: 0 | D28: 0 | E28: 0 | F28: 0 | G28: 0 | H28: 0 | I28: 0 | J28: 0
B29: Qtly | C29: =C23+D23+E23+C27+D27+E27 -> 7244 | F29: =F23+G23+H23+F27+G27+H27 -> 17201 | I29: =I23+J23+K23+I27+J27+K27 -> 10704 | L29: =L23+M23+N23+L27+M27+N27 -> 0
A30: AKSC | B30: Elec. Cons. (Kwhr) | C30: 0 | D30: 0 | E30: 0 | F30: 0 | G30: 0 | H30: 5378 | I30: 6691 | J30: 7600 | O30: =C30+D30+E30+F30+G30+H30+I30+J30+K30+L30+M30+N30 -> 19669
B31: Cost | C31: 0 | D31: 0 | E31: 0 | F31: 0 | G31: 0 | H31: 9906 | I31: 8931 | J31: 6492 | O31: =C31+D31+E31+F31+G31+H31+I31+J31+K31+L31+M31+N31 -> 25329
B32: MD-1 | C32: 10 | D32: 10 | E32: 10 | F32: 10 | G32: 10 | H32: 10 | I32: 10 | J32: 10
B33: Solar Gen(Kwhr) Import | C33: 1215.3 | D33: 1061.5 | E33: 1071.8 | F33: 8483 | G33: 10107 | H33: 11913 | I33: 13477 | J33: 14795 | O33: =SUM(C33:N33) -> 62123.6
B34: Solar Gen(Kwhr) Export | C34: {=+C37:E37+C43:E43+C49:E49+C55:E55+C61:E61+C65:E65} -> 22336 | D34: 25824 | E34: 24262 | F34: 4208 | G34: 4850 | H34: 5209 | I34: 5460 | J34: 5869
B35: Kwhr/Kwp | C35: =IF(C33="","",(C33/CONFIG!$B$6)/CONFIG!$B$3) -> 1.9601613 | D35: =IF(D33="","",(D33/CONFIG!$B$6)/CONFIG!$C$3) -> 1.8955357 | E35: =IF(E33="","",(E33/CONFIG!$B$6)/CONFIG!$D$3) -> 1.7287097 | F35: =IF(F33="","",(F33/CONFIG!$B$6)/CONFIG!$E$3) -> 14.138333 | G35: =IF(G33="","",(G33/CONFIG!$B$6)/CONFIG!$F$3) -> 16.301613 | H35: =IF(H33="","",(H33/CONFIG!$B$6)/CONFIG!$G$3) -> 19.855 | I35: =IF(I33="","",(I33/CONFIG!$B$6)/CONFIG!$H$3) -> 21.737097 | J35: =IF(J33="","",(J33/CONFIG!$B$6)/CONFIG!$I$3) -> 23.862903 | K35: =IF(K33="","",(K33/CONFIG!$B$6)/CONFIG!$J$3) | L35: =IF(L33="","",(L33/CONFIG!$B$6)/CONFIG!$K$3) | M35: =IF(M33="","",(M33/CONFIG!$B$6)/CONFIG!$L$3) | N35: =IF(N33="","",(N33/CONFIG!$B$6)/CONFIG!$M$3)
B36: Qtly | C36: =C30+D30+E30+C34+D34+E34 -> 72422 | F36: =F30+G30+H30+F34+G34+H34 -> 19645 | I36: =I30+J30+K30+I34+J34+K34 -> 25620 | L36: =L30+M30+N30+L34+M34+N34 -> 0
A37: DJHSH (PRI) | B37: Elec. Cons. (Kwhr) | C37: 783 | D37: 1022 | E37: 1065 | F37: 786 | G37: 531 | H37: 1165 | I37: 1300 | J37: 1330 | K37: 1187 | O37: =C37+D37+E37+F37+G37+H37+I37+J37+K37+L37+M37+N37 -> 9169
B38: Cost | C38: 9143 | D38: 11632 | E38: 12149 | F38: =7648+1494 -> 9142 | G38: 6147 | H38: =13295 -> 13295 | I38: 14805 | J38: 15043 | K38: 13538 | O38: =C38+D38+E38+F38+G38+H38+I38+J38+K38+L38+M38+N38 -> 104894
B39: MD (08)-1 | C39: 5.93 | D39: 7.43 | E39: 6.94 | F39: 2.25 | G39: 4.72 | H39: 7 | I39: 5.19 | J39: 7.59 | K39: 7.31
B40: Solar Gen(Kwhr) | C40: 0 | D40: 0 | E40: 0 | F40: 0 | G40: 0 | H40: 0 | I40: 0 | J40: 0 | K40: 0
B41: Cost | C41: 0 | D41: 0 | E41: 0 | F41: 0 | G41: 0 | H41: 0 | I41: 0 | J41: 0 | K41: 0
...

Sheet Water Consmp.
A1: AKESI - WATER CONSUMPTION LOG - 2026
A2: SCHOOL | C2: 46023 | D2: 46055 | E2: 46082 | F2: 46141 | G2: 46172 | H2: 46203 | I2: 46233 | J2: 46265 | K2: 46267 | L2: 46298 | M2: 46330 | N2: 46361 | O2: YTD Total / KPI
A3: DJHSM | B3: Liters | C3: =(3298.7-3240.3)*1000 -> 58400 | D3: =(3358.8-3298.7)*1000 -> 60100 | E3: =(3413.7-3358.8)*1000 -> 54900 | F3: =(3467.7-3413.7)*1000 -> 54000 | G3: =(3535.6-3467.7)*1000 -> 67900 | H3: =(3576-3535.6)*1000 -> 40400 | I3: =(3626.5-3576)*1000 -> 50500 | J3: =(3669.9-3626.5)*1000 -> 43400 | K3: =(3712.2-3669.9)*1000 -> 42300 | O3: =SUM(C3:N3) -> 471900 | P3: =C3+D3+E3+F3+G3+H3+I3+J3+K3+L3+M3+N3 -> 471900
B4: No. of pupils | C4: =1161+110 -> 1271 | D4: =1131+110 -> 1241 | E4: =1130+110 -> 1240 | F4: =1130+110 -> 1240 | G4: =10+13+9+9 -> 41 | H4: =1073+110 -> 1183 | I4: =1086+110 -> 1196 | J4: =1093+110 -> 1203 | K4: =1097+110 -> 1207
B5: Pupils Liter per day | C5: =IFERROR(C3/C4/C$43,0) -> 1.4821959 | D5: =IFERROR(D3/D4/D$43,0) -> 1.7295959 | E5: =IFERROR(E3/E4/E$43,0) -> 1.4281998 | F5: =IFERROR(F3/F4/F$43,0) -> 1.4516129 | G5: =IFERROR(G3/G4/G$43,0) -> 53.422502 | H5: =IFERROR(H3/H4/H$43,0) -> 1.1383488 | I5: =IFERROR(I3/I4/I$43,0) -> 1.3620671 | J5: =IFERROR(J3/J4/J$43,0) -> 1.1637573 | ... N5: =IFERROR(N3/N4/N$43,0) -> 0 | O5: =IFERROR(SUM(C3:N3)/(C4*C$43+D4*D$43+E4*E$43+F4*F$43+G4*G$43+H4*H$43+I4*I$43+J4*J$43+K4*K$43+L4*L$43+M4*M$43+N4*N$43),0) -> 1.5881991
B6: Amount
A7: DJG | B7: Liters | C7: 16184 | D7: 13357 | E7: 14763 | F7: 8947 | G7: 5991 | H7: 12743 | I7: =799569-783483 -> 16086 | J7: =814693-799569 -> 15124 | K7: =828129-814693 -> 13436 | O7: =SUM(C7:N7) -> 116631 | P7: =C7+D7+E7+F7+G7+H7+I7+J7+K7+L7+M7+N7 -> 116631
B8: No. of pupils | C8: 1010 | D8: 1010 | E8: 1010 | F8: 1008 | G8: 20 | H8: 1019 | I8: 1020 | J8: 1020 | K8: 1020
B9: Pupils Liter per day | C9: =IFERROR(C7/C8/C$43,0) -> 0.51689556 | D9: =IFERROR(D7/D8/D$43,0) -> 0.47231259 | E9: =IFERROR(E7/E8/E$43,0) -> 0.4715107 | F9: =IFERROR(F7/F8/F$43,0) -> 0.2958664 | G9: =IFERROR(G7/G8/G$43,0) -> 9.6629032 | H9: =IFERROR(H7/H8/H$43,0) -> 0.41684658 | I9: =IFERROR(I7/I8/I$43,0) -> 0.50872865 | J9: =IFERROR(J7/J8/J$43,0) -> 0.47830487 | ... N9: =IFERROR(N7/N8/N$43,0) -> 0 | O9: =IFERROR(SUM(C7:N7)/(C8*C$43+D8*D$43+E8*E$43+F8*F$43+G8*G$43+H8*H$43+I8*I$43+J8*J$43+K8*K$43+L8*L$43+M8*M$43+N8*N$43),0) -> 0.47378235
B10: Amount
A11: AKSS | B11: Liters | C11: 48300 | D11: 41200 | E11: 51200 | F11: 63600 | G11: 33800 | H11: 66300 | I11: 12000 | J11: 27900 | K11: 27900 | O11: =SUM(C11:N11) -> 372200 | P11: =C11+D11+E11+F11+G11+H11+I11+J11+K11+L11+M11+N11 -> 372200
B12: No. of pupils | C12: 505 | D12: 505 | E12: 505 | F12: 505 | G12: 25 | H12: 530 | I12: 530 | J12: 530 | K12: 530
B13: Pupils Liter per day | C13: =IFERROR(C11/C12/C$43,0) -> 3.0852763 | D13: =IFERROR(D11/D12/D$43,0) -> 2.9137199 | E13: =IFERROR(E11/E12/E$43,0) -> 3.2705206 | F13: =IFERROR(F11/F12/F$43,0) -> 4.1980198 | G13: =IFERROR(G11/G12/G$43,0) -> 43.612903 | H13: =IFERROR(H11/H12/H$43,0) -> 4.1698113 | I13: =IFERROR(I11/I12/I$43,0) -> 0.73037127 | J13: =IFERROR(J11/J12/J$43,0) -> 1.6981132 | ... N13: =IFERROR(N11/N12/N$43,0) -> 0 | O13: =IFERROR(SUM(C11:N11)/(C12*C$43+D12*D$43+E12*E$43+F12*F$43+G12*G$43+H12*H$43+I12*I$43+J12*J$43+K12*K$43+L12*L$43+M12*M$43+N12*N$43),0) -> 2.9531479
B14: Amount
A15: AKSC | B15: Liters | C15: 240000 | D15: 220000 | E15: 258000 | F15: 280000 | G15: 265000 | H15: 240000 | I15: 270000 | J15: 255000 | O15: =SUM(C15:N15) -> 2028000 | P15: =C15+D15+E15+F15+G15+H15+I15+J15+K15+L15+M15+N15 -> 2028000
B16: No. of pupils | C16: 347 | D16: 345 | E16: 345 | F16: 345 | G16: 345 | H16: 362 | I16: 370 | J16: 370
B17: Pupils Liter per day | C17: =IFERROR(C15/C16/C$43,0) -> 22.311053 | D17: =IFERROR(D15/D16/D$43,0) -> 22.774327 | E17: =IFERROR(E15/E16/E$43,0) -> 24.123422 | F17: =IFERROR(F15/F16/F$43,0) -> 27.05314 | G17: =IFERROR(G15/G16/G$43,0) -> 24.777934 | H17: =IFERROR(H15/H16/H$43,0) -> 22.099448 | I17: =IFERROR(I15/I16/I$43,0) -> 23.539669 | J17: =IFERROR(J15/J16/J$43,0) -> 22.231909 | ... N17: =IFERROR(N15/N16/N$43,0) -> 0 | O17: =IFERROR(SUM(C15:N15)/(C16*C$43+D16*D$43+E16*E$43+F16*F$43+G16*G$43+H16*H$43+I16*I$43+J16*J$43+K16*K$43+L16*L$43+M16*M$43+N16*N$43),0) -> 23.593192
B18: Amount
A19: AKSM | B19: Liters | C19: =(1771+1573)*1000-2909*1000 -> 435000 | D19: =(2044+1621)*1000-2909*1000-C19 -> 321000 | E19: =(2172+1702)*1000-2909*1000-D19-C19 -> 209000 | F19: =(2230+1735)*1000-2909*1000-E19-D19-C19 -> 91000 | G19: =(2340+1790)*1000-2909*1000-F19-E19-D19-C19 -> 165000 | H19: =(2490+1863)*1000-2909*1000-G19-F19-E19-D19-C19 -> 223000 | I19: =(2595+1943)*1000-2909*1000-H19-G19-F19-E19-C19-D19 -> 185000 | O19: =SUM(C19:N19) -> 1629000 | P19: =C19+D19+E19+F19+G19+H19+I19+J19+K19+L19+M19+N19 -> 1629000
B20: No. of pupils | C20: =700+45+16+50 -> 811 | D20: =700+45+16+50 -> 811 | E20: =650+45+16+45 -> 756 | F20: =650+45+16+45 -> 756 | G20: =650+45+16+45 -> 756 | H20: =650+45+16+45 -> 756 | I20: =720+45+16+45 -> 826
B21: Pupils Liter per day | C21: =IFERROR(C19/C20/C$43,0) -> 17.302414 | D21: =IFERROR(D19/D20/D$43,0) -> 14.135987 | E21: =IFERROR(E19/E20/E$43,0) -> 8.9179041 | F21: =IFERROR(F19/F20/F$43,0) -> 4.0123457 | G21: =IFERROR(G19/G20/G$43,0) -> 7.0404506 | H21: =IFERROR(H19/H20/H$43,0) -> 9.8324515 | I21: =IFERROR(I19/I20/I$43,0) -> 7.2248692 | J21: =IFERROR(J19/J20/J$43,0) -> 0 | ... N21: =IFERROR(N19/N20/N$43,0) -> 0 | O21: =IFERROR(SUM(C19:N19)/(C20*C$43+D20*D$43+E20*E$43+F20*F$43+G20*G$43+H20*H$43+I20*I$43+J20*J$43+K20*K$43+L20*L$43+M20*M$43+N20*N$43),0) -> 9.8317913
B22: Amount
A23: PJHSW | B23: Liters | C23: 558700 | D23: 569000 | E23: 565238 | F23: 380900 | G23: 256875 | H23: 446000 | I23: 659000 | J23: 669440 | K23: 699000 | O23: =SUM(C23:N23) -> 4804153 | P23: =C23+D23+E23+F23+G23+H23+I23+J23+K23+L23+M23+N23 -> 4804153
B24: No. of pupils | C24: 1445 | D24: 1445 | E24: 1445 | F24: 1445 | G24: 1445 | H24: 1384 | I24: 1400 | J24: 1400 | K24: 1422
B25: Pupils Liter per day | C25: =IFERROR(C23/C24/C$43,0) -> 12.472374 | D25: =IFERROR(D23/D24/D$43,0) -> 14.063272 | E25: =IFERROR(E23/E24/E$43,0) -> 12.618328 | F25: =IFERROR(F23/F24/F$43,0) -> 8.7866205 | G25: =IFERROR(G23/G24/G$43,0) -> 5.734457 | H25: =IFERROR(H23/H24/H$43,0) -> 10.741811 | I25: =IFERROR(I23/I24/I$43,0) -> 15.184332 | J25: =IFERROR(J23/J24/J$43,0) -> 15.424885 | ... N25: =IFERROR(N23/N24/N$43,0) -> 0 | O25: =IFERROR(SUM(C23:N23)/(C24*C$43+D24*D$43+E24*E$43+F24*F$43+G24*G$43+H24*H$43+I24*I$43+J24*J$43+K24*K$43+L24*L$43+M24*M$43+N24*N$43),0) -> 12.344454
B26: Amount
A27: LSHSA | B27: Liters | C27: 333860 | D27: 264500 | E27: 432756 | F27: 248950 | G27: 117348 | H27: 288354 | I27: 402336 | J27: 435889 | K27: 456330 | O27: =SUM(C27:N27) -> 2980323 | P27: =C27+D27+E27+F27+G27+H27+I27+J27+K27+L27+M27+N27 -> 2980323
B28: No. of pupils | C28: 1229 | D28: 1229 | E28: 1229 | F28: 1229 | G28: 22 | H28: 1151 | I28: =1081+73 -> 1154 | J28: 1154 | K28: =1082+72 -> 1154
B29: Pupils Liter per day | C29: =IFERROR(C27/C28/C$43,0) -> 8.7629597 | D29: =IFERROR(D27/D28/D$43,0) -> 7.6862722 | E29: =IFERROR(E27/E28/E$43,0) -> 11.358723 | F29: =IFERROR(F27/F28/F$43,0) -> 6.752102 | G29: =IFERROR(G27/G28/G$43,0) -> 172.06452 | H29: =IFERROR(H27/H28/H$43,0) -> 8.3508254 | I29: =IFERROR(I27/I28/I$43,0) -> 11.246604 | J29: =IFERROR(J27/J28/J$43,0) -> 12.184519 | ... N29: =IFERROR(N27/N28/N$43,0) -> 0 | O29: =IFERROR(SUM(C27:N27)/(C28*C$43+D28*D$43+E28*E$43+F28*F$43+G28*G$43+H28*H$43+I28*I$43+J28*J$43+K28*K$43+L28*L$43+M28*M$43+N28*N$43),0) -> 10.317534
B30: Amount
A31: DJHSH (P) | B31: Liters | C31: =31000+47000 -> 78000 | D31: =48000+33000 -> 81000 | E31: 71940 | F31: 65370 | G31: 52650 | H31: =46400+1361 -> 47761 | I31: =86900+55310 -> 142210 | J31: =51720+34200 -> 85920 | K31: =49360+28750 -> 78110 | O31: =SUM(C31:N31) -> 702961 | P31: =C31+D31+E31+F31+G31+H31+I31+J31+K31+L31+M31+N31 -> 702961
B32: No. of pupils | C32: 300 | D32: 300 | E32: 300 | F32: 300 | G32: 10 | H32: =265+23 -> 288 | I32: 288 | J32: 288 | K32: 288
B33: Pupils Liter per day | C33: =IFERROR(C31/C32/C$43,0) -> 8.3870968 | D33: =IFERROR(D31/D32/D$43,0) -> 9.6428571 | E33: =IFERROR(E31/E32/E$43,0) -> 7.7354839 | F33: =IFERROR(F31/F32/F$43,0) -> 7.2633333 | G33: =IFERROR(G31/G32/G$43,0) -> 169.83871 | H33: =IFERROR(H31/H32/H$43,0) -> 5.5278935 | I33: =IFERROR(I31/I32/I$43,0) -> 15.928539 | J33: =IFERROR(J31/J32/J$43,0) -> 9.6236559 | ... N33: =IFERROR(N31/N32/N$43,0) -> 0 | O33: =IFERROR(SUM(C31:N31)/(C32*C$43+D32*D$43+E32*E$43+F32*F$43+G32*G$43+H32*H$43+I32*I$43+J32*J$43+K32*K$43+L32*L$43+M32*M$43+N32*N$43),0) -> 9.8390533
B34: Amount
A35: DJHSH (H) | B35: Liters | C35: 225000 | D35: 174000 | E35: 130000 | F35: =160000+5000 -> 165000 | G35: =28000+38400 -> 66400 | H35: =49500+46100+11800 -> 107400 | I35: =61400+81800+25600 -> 168800 | J35: =41400+70700+57600 -> 169700 | K35: 141300 | O35: =SUM(C35:N35) -> 1347600 | P35: =C35+D35+E35+F35+G35+H35+I35+J35+K35+L35+M35+N35 -> 1347600
B36: No. of pupils | C36: 560 | D36: 560 | E36: 560 | F36: 560 | G36: 20 | H36: 600 | I36: 600 | J36: 600 | K36: 600
B37: Pupils Liter per day | C37: =IFERROR(C35/C36/C$43,0) -> 12.960829 | D37: =IFERROR(D35/D36/D$43,0) -> 11.096939 | E37: =IFERROR(E35/E36/E$43,0) -> 7.4884793 | F37: =IFERROR(F35/F36/F$43,0) -> 9.8214286 | G37: =IFERROR(G35/G36/G$43,0) -> 107.09677 | H37: =IFERROR(H35/H36/H$43,0) -> 5.9666667 | I37: =IFERROR(I35/I36/I$43,0) -> 9.0752688 | J37: =IFERROR(J35/J36/J$43,0) -> 9.1236559 | ... N37: =IFERROR(N35/N36/N$43,0) -> 0 | O37: =IFERROR(SUM(C35:N35)/(C36*C$43+D36*D$43+E36*E$43+F36*F$43+G36*G$43+H36*H$43+I36*I$43+J36*J$43+K36*K$43+L36*L$43+M36*M$43+N36*N$43),0) -> 9.5560913 | Q37: =1268.4-1257 -> 11.4
B38: Amount
A39: AKHH | B39: Liters | C39: 1351000 | D39: 1351000 | E39: 880000 | F39: 779000 | G39: 1051000 | H39: =1721*1000 -> 1721000 | I39: 1929000 | J39: 1634000 | K39: 1588000 | O39: =SUM(C39:N39) -> 12284000 | P39: =C39+D39+E39+F39+G39+H39+I39+J39+K39+L39+M39+N39 -> 12284000
B40: No. of pupils | C40: 140 | D40: 140 | E40: 140 | F40: 140 | G40: 90 | H40: =113+20+20 -> 153 | I40: =113+20+20 -> 153 | J40: =113+20+20 -> 153 | K40: =113+20+20 -> 153
...

Sheet REPAIRS
A1: AKESI Repairing Work -2026
A2: MONTH | B2: CATEGORY | C2: DJHSM | E2: DJG-M | G2: DJHSH | I2: AKHH | K2: PJHS | M2: LSHS | O2: AKSM | Q2: AKSS | S2: AKSC
C3: Total Tkt | D3: spent | E3: Total Tkt | F3: spent | G3: Total Tkt | H3: spent | I3: Total Tkt | J3: spent | K3: Total Tkt | L3: spent | M3: Total Tkt | N3: spent | O3: Total Tkt | P3: spent | Q3: Total Tkt | R3: spent | S3: Total Tkt | T3: spent
A4: JAN | B4: CIVIL | C4: 3 | D4: 11270 | G4: 0 | H4: 0 | I4: 2 | O4: 1 | P4: 8200 | Q4: 0 | R4: 0
B5: MECH | G5: 2 | H5: =2550+900 -> 3450 | I5: 3 | Q5: 0 | R5: 0
B6: ELE | E6: 1 | F6: 7500 | G6: 0 | H6: 0 | I6: 11 | K6: 2 | L6: =1575+3405 -> 4980 | M6: 1 | N6: 1100 | O6: 1 | P6: 7320 | Q6: 0 | R6: 0
B7: PLU | C7: 1 | D7: 180 | E7: 2 | F7: =1100+8430 -> 9530 | G7: 4 | H7: =2000+2950 -> 4950 | I7: 3 | K7: 2 | L7: =650+6060 -> 6710 | M7: 3 | N7: 2400 | O7: 4 | P7: 8710 | Q7: 0 | R7: 0
B8: CARPENTARY | C8: 1 | D8: 4200 | G8: 2 | H8: =1416+2313 -> 3729 | I8: 6 | J8: 0 | M8: 2 | N8: 1000 | O8: 4 | P8: 6822 | Q8: 0 | R8: 0
B9: R & M | C9: 2 | D9: 5416 | G9: 0 | H9: 0 | I9: 4 | M9: 1 | N9: 3980 | O9: 3 | P9: 5762 | Q9: 1 | R9: 1700 | S9: 4 | T9: 4556
B10: OTHERS & IT | C10: 2 | D10: 3820 | G10: 2 | H10: =5000+1800+2000 -> 8800 | I10: 0 | O10: 3 | P10: =1700+2006+4900 -> 8606 | Q10: 1 | R10: 650 | S10: 3 | T10: 4706
A11: FEB | B11: CIVIL | C11: 1 | D11: 950 | G11: 0 | I11: 0 | O11: 0 | P11: 0 | Q11: 0 | R11: 0
B12: MECH | E12: 1 | F12: 7000 | G12: 0 | I12: 3 | Q12: 0 | R12: 0
B13: ELE | E13: 3 | F13: =2035+1600+900 -> 4535 | G13: 16 | H13: =3000+5130+4430 -> 12560 | I13: 4 | K13: 2 | L13: =2200+1600 -> 3800 | M13: 4 | N13: 12310 | O13: 5 | P13: 2350 | Q13: 0 | R13: 0
B14: PLU | C14: 5 | D14: 5970 | G14: 4 | H14: =600+1250+1454+3540 -> 6844 | I14: 0 | M14: 3 | N14: 10390 | O14: 2 | P14: 8950 | Q14: 2 | R14: 8448
B15: CARPENTARY | C15: 2 | D15: 8400 | E15: 1 | F15: 7500 | G15: 16 | H15: =1840+1500+200+2400+4200+4930+2000+1809+4847 -> 23726 | I15: 0 | O15: 3 | P15: 780 | Q15: 0 | R15: 0
B16: R & M | E16: 1 | F16: 2950 | G16: 0 | H16: 0 | I16: 0 | Q16: 4 | R16: 6280 | S16: 7 | T16: 9564
B17: OTHERS & IT | C17: 4 | D17: 1096 | E17: 2 | F17: =1357+1770 -> 3127 | G17: 6 | H17: 2049 | I17: 0 | M17: 2 | N17: 6150 | O17: =2+1 -> 3 | P17: =2440+564 -> 3004 | Q17: 0 | R17: 0 | S17: 5 | T17: 18143
A18: MARCH | B18: CIVIL | C18: 4 | D18: 12580 | E18: 1 | F18: 8700 | G18: 0 | H18: 0 | I18: 0 | O18: 0 | P18: 0 | Q18: 0 | R18: 0
B19: MECH | C19: 1 | D19: 6880 | G19: 0 | H19: 0 | I19: 2 | O19: 0 | P19: 0 | Q19: 0 | R19: 0
B20: ELE | C20: 53 | D20: 26732 | G20: 5 | H20: =3754+1375 -> 5129 | I20: 12 | K20: 1 | L20: 1850 | M20: 3 | N20: 6850 | O20: 8 | P20: 5759 | Q20: 2 | R20: 1000
B21: PLU | E21: 1 | F21: 4500 | G21: 3 | H21: 1320 | I21: 9 | K21: 1 | L21: 2100 | M21: 2 | N21: 2950 | O21: 1 | P21: 2100 | Q21: 0 | R21: 0
B22: CARPENTARY | C22: 5 | D22: 13750 | G22: 2 | H22: =5900+375 -> 6275 | I22: 4 | M22: 1 | N22: 2700 | O22: 0 | P22: 0 | Q22: 1 | R22: 800
B23: R & M | G23: 0 | H23: 0 | I23: 12 | Q23: 3 | R23: 4700 | S23: 6 | T23: 7581
B24: OTHERS & IT | C24: 2 | D24: 1870 | E24: 1 | F24: 5841 | G24: 2 | H24: =4500+13000 -> 17500 | I24: 1 | M24: 1 | N24: 3600 | O24: 2 | P24: 2950 | Q24: 0 | R24: 0 | S24: 2 | T24: 3424
A25: APRIL | B25: CIVIL | C25: 5 | D25: 12469 | G25: 0 | I25: 2 | O25: 0 | P25: 0 | Q25: 0 | R25: 0
B26: MECH | C26: 3 | D26: 2800 | G26: 0 | I26: 12 | Q26: 0 | R26: 0
B27: ELE | C27: 2 | D27: 3755 | G27: 3 | H27: =5000+2500 -> 7500 | I27: 6 | K27: 1 | L27: =1850 -> 1850 | M27: 2 | N27: 4800 | O27: 3 | P27: 1671 | Q27: 2 | R27: 1800
B28: PLU | C28: 2 | D28: 3448 | E28: 4 | F28: =1500+20000+5782+2800 -> 30082 | G28: 0 | I28: 13 | K28: 1 | L28: 2500 | M28: 1 | N28: 4000 | O28: 2 | P28: 719 | Q28: 0 | R28: 0
B29: CARPENTARY | C29: 6 | D29: 11256 | E29: 1 | F29: 13500 | G29: 0 | I29: 11 | M29: 1 | N29: 1750 | O29: 2 | P29: 1933 | Q29: 0 | R29: 0
B30: R & M | C30: 3 | D30: 2783 | E30: 1 | F30: 12415 | G30: 0 | I30: 36 | M30: 2 | N30: 4250 | Q30: 5 | R30: 8500 | S30: 4 | T30: 4381
B31: OTHERS & IT | C31: 0 | D31: 0 | G31: 4 | H31: =8025+2000+4366 -> 14391 | I31: 0 | O31: =8 -> 8 | P31: =12740 -> 12740 | Q31: 0 | R31: 0 | S31: 2 | T31: 6200
A32: MAY | B32: CIVIL | I32: 3 | O32: 2 | P32: 10905 | Q32: 0 | R32: 0
B33: MECH | C33: 1 | D33: 4500 | I33: 9 | O33: 0 | P33: 0 | Q33: 0 | R33: 0
B34: ELE | C34: 1 | D34: 1164 | E34: 1 | F34: 2800 | I34: 12 | K34: 2 | L34: =6147+5955 -> 12102 | M34: 1 | N34: 7100 | O34: 4 | P34: 7465 | Q34: 0 | R34: 0
B35: PLU | I35: 16 | K35: 3 | L35: =4730+4830+1236 -> 10796 | O35: 0 | P35: 0 | Q35: 0 | R35: 0
B36: CARPENTARY | C36: 2 | D36: 5100 | G36: 1 | H36: 32800 | I36: 0 | K36: =2 -> 2 | L36: =9861+12390 -> 22251 | O36: 4 | P36: 6793 | Q36: 0 | R36: 0
B37: R & M | I37: 31 | K37: 0 | L37: 0 | M37: 1 | N37: 4200 | Q37: 1 | R37: 26700 | S37: 6 | T37: 7545
B38: OTHERS & IT | E38: 5 | F38: =4000+7700+6010+8400+4130 -> 30240 | I38: 0 | K38: 1 | L38: 8375 | O38: 3 | P38: 4500 | Q38: 0 | R38: 0 | S38: 6 | T38: 5624
A39: JUN | B39: CIVIL | C39: =2 -> 2 | D39: =17089 -> 17089 | E39: 1 | F39: 4600 | I39: 2 | O39: 8 | P39: 18800 | Q39: 0 | R39: 0
B40: MECH | I40: 10 | O40: 0 | P40: 0 | Q40: 0 | R40: 0
...

Sheet GENERATOR CONSMP.
A1: POWER - CONSUMPTION LOG (GENERATOR) - AKESI - 2026
A3: MONTH | B3: 46023 | C3: 46054 | D3: 46082 | E3: 46113 | F3: 46143 | G3: 46174 | H3: 46204 | I3: 46235 | J3: 46266 | K3: 46296 | L3: 46327 | M3: 46357
A4: AKSC - 16 kva
A5: Unit Consumed | B5: 20 | C5: 8 | D5: 21 | E5: 25 | F5: 23 | G5: 22 | H5: 28 | I5: 21
A6: Diesel consumption in (Liters) | B6: 21.89 | C6: 0 | D6: 21.89 | E6: 20 | F6: 20 | G6: 20 | H6: 40 | I6: 20 | J6: 20
A7: Run - Hours | B7: 10.5 | C7: 8 | D7: 12 | E7: 16 | F7: 13 | G7: 17 | H7: 32 | I7: 18 | J7: 18
A8: Quarterly | B8: =SUM(B6:D6) -> 43.78 | E8: =SUM(E6:G6) -> 60 | H8: =SUM(H6:J6) -> 80 | K8: =SUM(K6:M6) -> 0
A10: AKSM - 160 KVA
A11: Unit Consumed | B11: 50 | C11: 50 | D11: 70 | E11: 73 | F11: 75 | G11: 69 | H11: 141 | I11: 49 | N11: =50*9 -> 450
A12: Diesel consumption in (Liters) | B12: 80 | C12: 80 | D12: 100 | E12: 0 | F12: 0 | G12: 40 | H12: 203.38 | I12: 204.08 | J12: 0
A13: Run - Hours | B13: 8 | C13: 8 | D13: 10 | E13: 11 | F13: 11 | G13: 10 | H13: 24 | I13: 8
A14: Quarterly | B14: =SUM(B12:D12) -> 260 | E14: =SUM(E12:G12) -> 40 | H14: =SUM(H12:J12) -> 407.46 | K14: =SUM(K12:M12) -> 0
A16: AKHH - 63 KVA
A17: Unit Consumed (KWH) | B17: 75.7 | C17: 92.3 | D17: 472.2 | E17: 285 | F17: 261.5 | G17: 579 | H17: 467 | I17: 116 | J17: 149.1
A18: Diesel consumption in (Liters) | B18: 70 | C18: 95 | D18: 160 | E18: 140 | F18: 120 | G18: 140 | H18: 200 | I18: 115 | J18: 40
A19: Run - Hours | B19: 5.18 | C19: 5.42 | D19: 29.35 | E19: 20.49 | F19: 26.49 | G19: 36 | H19: 36.7 | I19: 12 | J19: 11.06
A20: Quarterly | B20: =SUM(B18:D18) -> 325 | E20: =SUM(E18:G18) -> 400 | H20: =SUM(H18:J18) -> 355 | K20: =SUM(K18:M18) -> 0

Sheet WATER TESTS
A1: PARAMETERS | D1: Note: Every Halfterys should done with NABL accrediated lab (like Q2 & Q4 or Q1 & Q3) | H1: CHEMICAL PARAMETERS | V1: MICROBIOLOGICAL PARAMETERS
A2: PARAMETERS Sub Classification Bore Well | D2: Colour | E2: Turbidity | F2: pH | G2: Electrical Conductivity | H2: Total Dissolved Solids | I2: Total Hardness as Caco3 | J2: Alkalilnity to Phenolphthalein | K2: Methyl Orange Alkalinity | L2: Calcium as Ca, | M2: Magnesium as Mg | N2: Soldium as Na, | O2: Potassium as K, | P2: Chloride as Cl, | Q2: Sulphates as S04, | R2: Nitrates as No3, | S2: Fluoride as F | T2: Iron | U2: Silica | V2: Total Bacterial Count | W2: Coli form | X2: E coli
A3: UNITS | D3: Hazen | E3: NTU | G3: Us/cm | H3: mg/l | I3: mg/l | J3: mg/l | K3: mg/l | L3: mg/l | M3: mg/l | N3: mg/l | O3: mg/l | P3: mg/l | Q3: mg/l | R3: mg/l | S3: mg/l | T3: mg/l | U3: mg/l | V3: Cfu/ml | W3: MPN/100ml
A4: DESIRABLE LIMITS | D4: 5 | E4: 1 | F4: 6.5 - 8.5 | G4: 500-1500 | H4: 500 | I4: 200 | J4: NS | K4: 200 | L4: 75 | M4: 30 | N4: NS | O4: NS | P4: 250 | Q4: 200 | R4: 45 | S4: 1 | T4: 0.3 | U4: 10 - 50 | V4: NS | W4: Nil | X4: Absent 100ml
A5: DJHSM | B5: Q1 | C5: At Source | D5: 3 | E5: <1 | F5: 7.22 | G5: - | H5: 50 | I5: 10 | J5: 8 | L5: 8.4 | P5: 11.5 | Q5: 1.13 | R5: 1.22 | S5: BDL | T5: 0.06 | V5: absent | W5: absent | X5: absent
C6: Drinking Water | D6: 3 | E6: <1 | F6: 7.13 | H6: 55 | I6: 14 | J6: 10 | L6: 10.5 | P6: 12 | Q6: 1.17 | R6: 1.3 | S6: BDL | T6: 0.1 | V6: absent | W6: absent | X6: absent
B7: Q2 | C7: At Source | D7: 3 | E7: <1 | F7: 6.87 | H7: 85 | I7: 18 | J7: 12 | L7: 12.6 | P7: 27.5 | Q7: 1.85 | R7: 1.7 | S7: BDL | T7: 0.1 | V7: absent | W7: absent | X7: absent
C8: Drinking Water | D8: 3 | E8: <1 | F8: 6.9 | H8: 80 | I8: 18 | J8: 12 | L8: 12.6 | P8: 24 | Q8: 1.8 | R8: 1.68 | S8: BDL | T8: 0.1 | V8: absent | W8: absent | X8: absent
B9: Q3 | C9: At Source
C10: Drinking Water
B11: Q4 | C11: At Source
C12: Drinking Water
A13: DJG | B13: Q1 | C13: At Source | D13: 3 | E13: <1 | F13: 7.16 | H13: 86 | I13: 26 | J13: 16 | L13: 16.8 | P13: 15 | Q13: 1.72 | R13: 1.4 | S13: BDL | T13: 0.1 | V13: ABSENT | W13: ABSENT | X13: ABSENT
C14: Drinking Water | D14: 3 | E14: <1 | F14: 7.14 | H14: 84 | I14: 18 | J14: 12 | L14: 12.6 | P14: 14 | Q14: 1.6 | R14: 1.4 | S14: BDL | T14: 0.1 | V14: ABSENT | W14: ABSENT | X14: ABSENT
B15: Q2 | C15: At Source | D15: 3 | E15: <1 | F15: 6.8 | H15: 90 | I15: 22 | J15: 14 | L15: 14.7 | P15: 35 | Q15: 1.85 | R15: 1.3 | S15: BDL | T15: 0.1 | V15: ABSENT | W15: ABSENT | X15: ABSENT
C16: Drinking Water | D16: 3 | E16: <1 | F16: 6.78 | H16: 80 | I16: 18 | J16: 12 | L16: 12.6 | P16: 35 | Q16: 1.8 | R16: 1.2 | S16: BDL | T16: 0.1 | V16: ABSENT | W16: ABSENT | X16: ABSENT
B17: Q3 | C17: At Source
C18: Drinking Water
B19: Q4 | C19: At Source
C20: Drinking Water
A21: AKSS | B21: Q1 | C21: At Source (WELL) | D21: 2 | E21: 1.58 | F21: 7.78 | G21: - | H21: 918 | I21: 228 | J21: 296 | K21: - | L21: 62 | M21: 18 | N21: - | O21: - | P21: 272 | Q21: 70 | R21: 58.15 | S21: 1.99 | T21: - | U21: - | V21: - | W21: - | X21: -
C22: Drinking Water | D22: 1 | E22: 0.71 | F22: 7.83 | G22: - | H22: 310 | I22: 132 | J22: 84 | K22: - | L22: 34 | M22: 11 | N22: - | O22: - | P22: 64 | Q22: 15 | R22: 15.1 | S22: 0.18 | T22: - | U22: - | V22: - | W22: - | X22: -
B23: Q2 | C23: At Source (WELL) | D23: 2 | E23: 1.87 | F23: 7.52 | G23: - | H23: 1232 | I23: 480 | J23: 260 | K23: - | L23: 132 | M23: 36 | N23: - | O23: - | P23: 276 | Q23: 98 | R23: 150 | S23: 0.43 | T23: - | U23: - | V23: - | W23: - | X23: -
C24: Drinking Water | D24: 1 | E24: 1.23 | F24: 7.99 | G24: - | H24: 226 | I24: 76 | J24: 42 | K24: - | L24: 15 | M24: 9 | N24: - | O24: - | P24: 48 | Q24: 11 | R24: 56.9 | S24: 0.21 | T24: - | U24: - | V24: - | W24: - | X24: -
B25: Q3 | C25: At Source (WELL)
C26: Drinking Water
B27: Q4 | C27: At Source (WELL)
C28: Drinking Water
A29: AKSC | B29: Q1 | C29: At Source
C30: Drinking Water
B31: Q2 | C31: At Source
C32: Drinking Water
B33: Q3 | C33: At Source -BW
C34: Drinking Water
B35: Q4 | C35: At Source
C36: Drinking Water
A37: AKSM | B37: Q1 | C37: At Source -Mun | D37: 1 | E37: 1.87 | F37: 7.85 | G37: 0 | H37: 1856 | I37: 496 | J37: 476 | K37: 0 | L37: 115 | M37: 51 | N37: 0 | O37: 0 | P37: 660 | Q37: 202 | R37: 6.65 | S37: 0.68 | T37: 0 | U37: 0 | V37: ABSENT | W37: ABSENT | X37: ABSENT
C38: At Source -BW | D38: 1 | E38: 1.56 | F38: 7.25 | G38: 0 | H38: 2410 | I38: 660 | J38: 620 | K38: 0 | L38: 160 | M38: 63 | N38: 0 | O38: 0 | P38: 808 | Q38: 268 | R38: 6.65 | S38: 0.61 | T38: 0 | U38: 0 | V38: ABSENT | W38: ABSENT | X38: ABSENT
C39: Drinking Water- RO | D39: 1 | E39: 0.18 | F39: 7.02 | G39: 0 | H39: 162 | I39: 32 | J39: 68 | K39: 0 | L39: 8 | M39: 3 | N39: 0 | O39: 0 | P39: 40 | Q39: 10 | R39: 2.22 | S39: 0.12 | T39: 0 | U39: 0 | V39: ABSENT | W39: ABSENT | X39: ABSENT
B40: Q2 | C40: At Source -Mun
...

Sheet AMC-LOG
A1: AKESI - AMC LOG - 2026 | U1: AUDIT CONTROL
A2: SCHOOL | B2: AMC | C2: START DT. | D2: EXP DT. | E2: Service Type | F2: Service Provider | G2: cost of Service | H2: 46023 | I2: 46055 | J2: 46082 | K2: 46141 | L2: 46172 | M2: 46203 | N2: 46233 | O2: 46265 | P2: 46267 | Q2: 46298 | R2: 46330 | S2: 46361 | T2: Remarks | U2: Status
A3: DJHSM | B3: ELECTRICAL | U3: =IF(B3="","",IF(OR(C3="",D3=""),"INCOMPLETE",IF(C3>D3,"DATE ERROR",IF(D3<CONFIG!$B$8,"EXPIRED",IF(D3<=CONFIG!$B$8+30,"EXPIRING <=30D",IF(D3<=CONFIG!$B$8+90,"EXPIRING <=90D","ACTIVE")))))) -> INCOMPLETE
B4: PLUMBING | U4: =IF(B4="","",IF(OR(C4="",D4=""),"INCOMPLETE",IF(C4>D4,"DATE ERROR",IF(D4<CONFIG!$B$8,"EXPIRED",IF(D4<=CONFIG!$B$8+30,"EXPIRING <=30D",IF(D4<=CONFIG!$B$8+90,"EXPIRING <=90D","ACTIVE")))))) -> INCOMPLETE
B5: FIRE SYSTEM | C5: 46204 | D5: 46934 | E5: Non-Comprehensive | F5: Mauli Fire Safety Services | G5: 47200 | N5: 11800 | Q5: 11800 | U5: =IF(B5="","",IF(OR(C5="",D5=""),"INCOMPLETE",IF(C5>D5,"DATE ERROR",IF(D5<CONFIG!$B$8,"EXPIRED",IF(D5<=CONFIG!$B$8+30,"EXPIRING <=30D",IF(D5<=CONFIG!$B$8+90,"EXPIRING <=90D","ACTIVE")))))) -> ACTIVE
B6: AIRCONDTION | G6: 10400 | H6: 2600 (2027) | K6: 2600 (2027) | N6: 2600 | Q6: 2600 | U6: =IF(B6="","",IF(OR(C6="",D6=""),"INCOMPLETE",IF(C6>D6,"DATE ERROR",IF(D6<CONFIG!$B$8,"EXPIRED",IF(D6<=CONFIG!$B$8+30,"EXPIRING <=30D",IF(D6<=CONFIG!$B$8+90,"EXPIRING <=90D","ACTIVE")))))) -> INCOMPLETE
B7: PEST CONTROL | C7: 45809 | D7: 46173 | E7: Non-Comprehensive | F7: PEST SHIELD | G7: 106386 | H7: 15198 | I7: 15198 | J7: 15198 | K7: 15198 | L7: 15198 | U7: =IF(B7="","",IF(OR(C7="",D7=""),"INCOMPLETE",IF(C7>D7,"DATE ERROR",IF(D7<CONFIG!$B$8,"EXPIRED",IF(D7<=CONFIG!$B$8+30,"EXPIRING <=30D",IF(D7<=CONFIG!$B$8+90,"EXPIRING <=90D","ACTIVE")))))) -> EXPIRED
B8: RO/UF/WTP | C8: 45962 | D8: 46326 | E8: Non-Comprehensive | F8: ACE Hygeinic products Pvt. ltd | G8: 6900 | U8: =IF(B8="","",IF(OR(C8="",D8=""),"INCOMPLETE",IF(C8>D8,"DATE ERROR",IF(D8<CONFIG!$B$8,"EXPIRED",IF(D8<=CONFIG!$B$8+30,"EXPIRING <=30D",IF(D8<=CONFIG!$B$8+90,"EXPIRING <=90D","ACTIVE")))))) -> EXPIRING <=30D
B9: ELEVATOR | D9: 46203 | E9: Gold Contract | F9: TK Elevator India Pvt. Ltd. | G9: 224448 | H9: 224448 | U9: =IF(B9="","",IF(OR(C9="",D9=""),"INCOMPLETE",IF(C9>D9,"DATE ERROR",IF(D9<CONFIG!$B$8,"EXPIRED",IF(D9<=CONFIG!$B$8+30,"EXPIRING <=30D",IF(D9<=CONFIG!$B$8+90,"EXPIRING <=90D","ACTIVE")))))) -> INCOMPLETE
A10: DJG | B10: ELECTRICAL | U10: =IF(B10="","",IF(OR(C10="",D10=""),"INCOMPLETE",IF(C10>D10,"DATE ERROR",IF(D10<CONFIG!$B$8,"EXPIRED",IF(D10<=CONFIG!$B$8+30,"EXPIRING <=30D",IF(D10<=CONFIG!$B$8+90,"EXPIRING <=90D","ACTIVE")))))) -> INCOMPLETE
B11: PLUMBING | U11: =IF(B11="","",IF(OR(C11="",D11=""),"INCOMPLETE",IF(C11>D11,"DATE ERROR",IF(D11<CONFIG!$B$8,"EXPIRED",IF(D11<=CONFIG!$B$8+30,"EXPIRING <=30D",IF(D11<=CONFIG!$B$8+90,"EXPIRING <=90D","ACTIVE")))))) -> INCOMPLETE
B12: FIRE SYSTEM | E12: Non-Comprehensive | F12: Mauli Fire Safety Services | G12: 40000 | U12: =IF(B12="","",IF(OR(C12="",D12=""),"INCOMPLETE",IF(C12>D12,"DATE ERROR",IF(D12<CONFIG!$B$8,"EXPIRED",IF(D12<=CONFIG!$B$8+30,"EXPIRING <=30D",IF(D12<=CONFIG!$B$8+90,"EXPIRING <=90D","ACTIVE")))))) -> INCOMPLETE
B13: AIRCONDTION | U13: =IF(B13="","",IF(OR(C13="",D13=""),"INCOMPLETE",IF(C13>D13,"DATE ERROR",IF(D13<CONFIG!$B$8,"EXPIRED",IF(D13<=CONFIG!$B$8+30,"EXPIRING <=30D",IF(D13<=CONFIG!$B$8+90,"EXPIRING <=90D","ACTIVE")))))) -> INCOMPLETE
B14: RO/UF/WTP | U14: =IF(B14="","",IF(OR(C14="",D14=""),"INCOMPLETE",IF(C14>D14,"DATE ERROR",IF(D14<CONFIG!$B$8,"EXPIRED",IF(D14<=CONFIG!$B$8+30,"EXPIRING <=30D",IF(D14<=CONFIG!$B$8+90,"EXPIRING <=90D","ACTIVE")))))) -> INCOMPLETE
A15: AKSM | B15: PEST CONTROL | C15: 46113 | D15: 46843 | E15: Non-Comprehensive | F15: PCI-PEST CONTROL PVT LTD | U15: =IF(B15="","",IF(OR(C15="",D15=""),"INCOMPLETE",IF(C15>D15,"DATE ERROR",IF(D15<CONFIG!$B$8,"EXPIRED",IF(D15<=CONFIG!$B$8+30,"EXPIRING <=30D",IF(D15<=CONFIG!$B$8+90,"EXPIRING <=90D","ACTIVE")))))) -> ACTIVE
B16: Air Condition | C16: 46204 | D16: 46934 | E16: Non-Comprehensive | F16: Sama Electric | G16: =(11*2800)+(11*2800)*18% -> 36344 | H16: 0 | I16: 0 | J16: 0 | K16: 0 | L16: 0 | M16: 0 | U16: =IF(B16="","",IF(OR(C16="",D16=""),"INCOMPLETE",IF(C16>D16,"DATE ERROR",IF(D16<CONFIG!$B$8,"EXPIRED",IF(D16<=CONFIG!$B$8+30,"EXPIRING <=30D",IF(D16<=CONFIG!$B$8+90,"EXPIRING <=90D","ACTIVE")))))) -> ACTIVE
B17: Photocopier Machine | C17: 46023 | D17: 46387 | E17: Non-Comprehensive | F17: Fortune Sales Agency | G17: 0.39 | U17: =IF(B17="","",IF(OR(C17="",D17=""),"INCOMPLETE",IF(C17>D17,"DATE ERROR",IF(D17<CONFIG!$B$8,"EXPIRED",IF(D17<=CONFIG!$B$8+30,"EXPIRING <=30D",IF(D17<=CONFIG!$B$8+90,"EXPIRING <=90D","ACTIVE")))))) -> EXPIRING <=90D
B18: PLUMBING | U18: =IF(B18="","",IF(OR(C18="",D18=""),"INCOMPLETE",IF(C18>D18,"DATE ERROR",IF(D18<CONFIG!$B$8,"EXPIRED",IF(D18<=CONFIG!$B$8+30,"EXPIRING <=30D",IF(D18<=CONFIG!$B$8+90,"EXPIRING <=90D","ACTIVE")))))) -> INCOMPLETE
B19: Internet | C19: 46204 | D19: 46568 | E19: Internet 200MBPS | F19: Ishan Netsol Pvt Ltd | U19: =IF(B19="","",IF(OR(C19="",D19=""),"INCOMPLETE",IF(C19>D19,"DATE ERROR",IF(D19<CONFIG!$B$8,"EXPIRED",IF(D19<=CONFIG!$B$8+30,"EXPIRING <=30D",IF(D19<=CONFIG!$B$8+90,"EXPIRING <=90D","ACTIVE")))))) -> ACTIVE
B20: H.K. Materials | C20: 46113 | D20: 46843 | F20: POP Online Services Pvt Ltd | G20: As per need | U20: =IF(B20="","",IF(OR(C20="",D20=""),"INCOMPLETE",IF(C20>D20,"DATE ERROR",IF(D20<CONFIG!$B$8,"EXPIRED",IF(D20<=CONFIG!$B$8+30,"EXPIRING <=30D",IF(D20<=CONFIG!$B$8+90,"EXPIRING <=90D","ACTIVE")))))) -> ACTIVE
B21: Contract of HK | C21: 44927 | D21: 46387 | F21: M/s. Sky Touch Security & Allied Service | U21: =IF(B21="","",IF(OR(C21="",D21=""),"INCOMPLETE",IF(C21>D21,"DATE ERROR",IF(D21<CONFIG!$B$8,"EXPIRED",IF(D21<=CONFIG!$B$8+30,"EXPIRING <=30D",IF(D21<=CONFIG!$B$8+90,"EXPIRING <=90D","ACTIVE")))))) -> EXPIRING <=90D
B22: Contract of Security | C22: 44927 | D22: 46387 | F22: M/s. Sky Touch Security & Allied Service | U22: =IF(B22="","",IF(OR(C22="",D22=""),"INCOMPLETE",IF(C22>D22,"DATE ERROR",IF(D22<CONFIG!$B$8,"EXPIRED",IF(D22<=CONFIG!$B$8+30,"EXPIRING <=30D",IF(D22<=CONFIG!$B$8+90,"EXPIRING <=90D","ACTIVE")))))) -> EXPIRING <=90D
B23: STATIONERY | C23: 45839 | D23: 46203 | F23: Shah Premji Ratanshi | G23: As per need | U23: =IF(B23="","",IF(OR(C23="",D23=""),"INCOMPLETE",IF(C23>D23,"DATE ERROR",IF(D23<CONFIG!$B$8,"EXPIRED",IF(D23<=CONFIG!$B$8+30,"EXPIRING <=30D",IF(D23<=CONFIG!$B$8+90,"EXPIRING <=90D","ACTIVE")))))) -> EXPIRED
B24: FIRE SYSTEM | C24: 45839 | D24: 46203 | E24: Non-Comprehensive | F24: Vijay Fire Station | G24: 38000 | U24: =IF(B24="","",IF(OR(C24="",D24=""),"INCOMPLETE",IF(C24>D24,"DATE ERROR",IF(D24<CONFIG!$B$8,"EXPIRED",IF(D24<=CONFIG!$B$8+30,"EXPIRING <=30D",IF(D24<=CONFIG!$B$8+90,"EXPIRING <=90D","ACTIVE")))))) -> EXPIRED
B25: RO/UF/WTP | U25: =IF(B25="","",IF(OR(C25="",D25=""),"INCOMPLETE",IF(C25>D25,"DATE ERROR",IF(D25<CONFIG!$B$8,"EXPIRED",IF(D25<=CONFIG!$B$8+30,"EXPIRING <=30D",IF(D25<=CONFIG!$B$8+90,"EXPIRING <=90D","ACTIVE")))))) -> INCOMPLETE
B26: GENERATOR | U26: =IF(B26="","",IF(OR(C26="",D26=""),"INCOMPLETE",IF(C26>D26,"DATE ERROR",IF(D26<CONFIG!$B$8,"EXPIRED",IF(D26<=CONFIG!$B$8+30,"EXPIRING <=30D",IF(D26<=CONFIG!$B$8+90,"EXPIRING <=90D","ACTIVE")))))) -> INCOMPLETE
A27: AKSS | B27: ELECTRICAL | F27: - | G27: - | H27: - | I27: - | J27: - | K27: - | L27: - | M27: - | N27: - | O27: - | P27: - | U27: =IF(B27="","",IF(OR(C27="",D27=""),"INCOMPLETE",IF(C27>D27,"DATE ERROR",IF(D27<CONFIG!$B$8,"EXPIRED",IF(D27<=CONFIG!$B$8+30,"EXPIRING <=30D",IF(D27<=CONFIG!$B$8+90,"EXPIRING <=90D","ACTIVE")))))) -> INCOMPLETE
B28: PLUMBING | F28: - | G28: - | H28: - | I28: - | J28: - | K28: - | L28: - | M28: - | N28: - | O28: - | P28: - | U28: =IF(B28="","",IF(OR(C28="",D28=""),"INCOMPLETE",IF(C28>D28,"DATE ERROR",IF(D28<CONFIG!$B$8,"EXPIRED",IF(D28<=CONFIG!$B$8+30,"EXPIRING <=30D",IF(D28<=CONFIG!$B$8+90,"EXPIRING <=90D","ACTIVE")))))) -> INCOMPLETE
B29: FIRE SYSTEM | E29: Non-Comprehensive | F29: S. K. Enterpirse | G29: 18,000/- | H29: - | I29: - | J29: - | K29: 4,500/- | L29: - | M29: - | N29: - | O29: - | P29: 12,200/- | U29: =IF(B29="","",IF(OR(C29="",D29=""),"INCOMPLETE",IF(C29>D29,"DATE ERROR",IF(D29<CONFIG!$B$8,"EXPIRED",IF(D29<=CONFIG!$B$8+30,"EXPIRING <=30D",IF(D29<=CONFIG!$B$8+90,"EXPIRING <=90D","ACTIVE")))))) -> INCOMPLETE
B30: STATIONERY | E30: Consumable item | F30: Dhoni Stationery Mart | G30: - | H30: 12,000/- | I30: - | J30: - | K30: - | L30: - | M30: - | N30: - | O30: - | P30: - | U30: =IF(B30="","",IF(OR(C30="",D30=""),"INCOMPLETE",IF(C30>D30,"DATE ERROR",IF(D30<CONFIG!$B$8,"EXPIRED",IF(D30<=CONFIG!$B$8+30,"EXPIRING <=30D",IF(D30<=CONFIG!$B$8+90,"EXPIRING <=90D","ACTIVE")))))) -> INCOMPLETE
B31: SECURITY GUARD | E31: Security | F31: Manforce Security Services | G31: 53,596.62/- | H31: 54,818/- | I31: 53,919/- | J31: 44,633/- | K31: 56,439/- | L31: 56,439/- | M31: 55,825/- | N31: 55,212/- | O31: 54,598/- | P31: 57,052/- | U31: =IF(B31="","",IF(OR(C31="",D31=""),"INCOMPLETE",IF(C31>D31,"DATE ERROR",IF(D31<CONFIG!$B$8,"EXPIRED",IF(D31<=CONFIG!$B$8+30,"EXPIRING <=30D",IF(D31<=CONFIG!$B$8+90,"EXPIRING <=90D","ACTIVE")))))) -> INCOMPLETE
B32: HOUSEKEEPING STAFF | E32: Housekeeping | F32: Smartline Facility Management Pvt. Ltd. | G32: 1,09,502.75/- | H32: 1,00,018/- | I32: 86,967/- | J32: 85,474/- | K32: 99,987/- | L32: 86,529/- | M32: 91,728/- | N32: 99,986/- | O32: 1,07,021/- | P32: 1,08,245/- | U32: =IF(B32="","",IF(OR(C32="",D32=""),"INCOMPLETE",IF(C32>D32,"DATE ERROR",IF(D32<CONFIG!$B$8,"EXPIRED",IF(D32<=CONFIG!$B$8+30,"EXPIRING <=30D",IF(D32<=CONFIG!$B$8+90,"EXPIRING <=90D","ACTIVE")))))) -> INCOMPLETE
B33: PEST CONTROL | E33: Non-Comprehensive | F33: Pest Control Pvt. Ltd. | G33: 47,484/- (excd. GST) | H33: 4,669/- | I33: 4,669/- | J33: 4,669/- | K33: - | L33: 4,669/- | M33: - | N33: - | O33: - | P33: - | U33: =IF(B33="","",IF(OR(C33="",D33=""),"INCOMPLETE",IF(C33>D33,"DATE ERROR",IF(D33<CONFIG!$B$8,"EXPIRED",IF(D33<=CONFIG!$B$8+30,"EXPIRING <=30D",IF(D33<=CONFIG!$B$8+90,"EXPIRING <=90D","ACTIVE")))))) -> INCOMPLETE
B34: AIR CONDTION | C34: 46204 | D34: 46203 | E34: AC Service | F34: Superb Cool Service | H34: - | I34: - | J34: - | K34: - | L34: - | M34: - | N34: 4,450/- | O34: - | P34: - | U34: =IF(B34="","",IF(OR(C34="",D34=""),"INCOMPLETE",IF(C34>D34,"DATE ERROR",IF(D34<CONFIG!$B$8,"EXPIRED",IF(D34<=CONFIG!$B$8+30,"EXPIRING <=30D",IF(D34<=CONFIG!$B$8+90,"EXPIRING <=90D","ACTIVE")))))) -> DATE ERROR
A35: AKSC | B35: ELECTRICAL | N35: 0 | O35: 0 | U35: =IF(B35="","",IF(OR(C35="",D35=""),"INCOMPLETE",IF(C35>D35,"DATE ERROR",IF(D35<CONFIG!$B$8,"EXPIRED",IF(D35<=CONFIG!$B$8+30,"EXPIRING <=30D",IF(D35<=CONFIG!$B$8+90,"EXPIRING <=90D","ACTIVE")))))) -> INCOMPLETE
B36: PLUMBING | N36: 0 | O36: 0 | U36: =IF(B36="","",IF(OR(C36="",D36=""),"INCOMPLETE",IF(C36>D36,"DATE ERROR",IF(D36<CONFIG!$B$8,"EXPIRED",IF(D36<=CONFIG!$B$8+30,"EXPIRING <=30D",IF(D36<=CONFIG!$B$8+90,"EXPIRING <=90D","ACTIVE")))))) -> INCOMPLETE
B37: FIRE SYSTEM | C37: 46204 | D37: 46934 | E37: Non-Comprehensive | F37: Vijay Fire System | N37: 6000/- | O37: 0 | U37: =IF(B37="","",IF(OR(C37="",D37=""),"INCOMPLETE",IF(C37>D37,"DATE ERROR",IF(D37<CONFIG!$B$8,"EXPIRED",IF(D37<=CONFIG!$B$8+30,"EXPIRING <=30D",IF(D37<=CONFIG!$B$8+90,"EXPIRING <=90D","ACTIVE")))))) -> ACTIVE
B38: AIRCONDTION | C38: 46204 | D38: 46934 | E38: Non-Comprehensive | F38: KISMAT REFRIGERATOR | N38: 3600/- | O38: 0 | U38: =IF(B38="","",IF(OR(C38="",D38=""),"INCOMPLETE",IF(C38>D38,"DATE ERROR",IF(D38<CONFIG!$B$8,"EXPIRED",IF(D38<=CONFIG!$B$8+30,"EXPIRING <=30D",IF(D38<=CONFIG!$B$8+90,"EXPIRING <=90D","ACTIVE")))))) -> ACTIVE
B39: RO/UF/WTP | N39: 0 | O39: 0 | U39: =IF(B39="","",IF(OR(C39="",D39=""),"INCOMPLETE",IF(C39>D39,"DATE ERROR",IF(D39<CONFIG!$B$8,"EXPIRED",IF(D39<=CONFIG!$B$8+30,"EXPIRING <=30D",IF(D39<=CONFIG!$B$8+90,"EXPIRING <=90D","ACTIVE")))))) -> INCOMPLETE
B40: GENERATOR | N40: 0 | O40: 0 | P40: 8260/- | U40: =IF(B40="","",IF(OR(C40="",D40=""),"INCOMPLETE",IF(C40>D40,"DATE ERROR",IF(D40<CONFIG!$B$8,"EXPIRED",IF(D40<=CONFIG!$B$8+30,"EXPIRING <=30D",IF(D40<=CONFIG!$B$8+90,"EXPIRING <=90D","ACTIVE")))))) -> INCOMPLETE
...

Sheet check list
A1: FAC-MIS 2026 – MANAGEMENT DATA CHECKLIST
A2: Report | B2: Latest Source Month/Quarter | C2: Coverage | D2: Status | E2: Action
A3: Electricity Consumption | B3: Sep-2026 | C3: 9 / 12 months | D3: INCOMPLETE | E3: Update Oct-Dec readings
A4: Solar Generation | B4: Sep-2026 | C4: 9 / 12 months | D4: INCOMPLETE | E4: Update Oct-Dec source readings
A5: Water Consumption | B5: Sep-2026 | C5: 9 / 12 months | D5: INCOMPLETE | E5: Update Oct-Dec readings
A6: Water Test | B6: Q2-2026 | C6: 2 / 4 quarters | D6: INCOMPLETE | E6: Complete Q3/Q4 tests & certificates
A7: Generator Consumption | B7: Sep-2026 | C7: 9 / 12 months | D7: INCOMPLETE | E7: Update Oct-Dec readings
A8: AMC Log | B8: 05-Oct-2026 | C8: Current register | D8: REVIEW | E8: Close 12 expired / 1 date-error records

Sheet CONFIG
A1: FAC-MIS 2026 – CONTROL CONFIGURATION | P1: Status | Q1: Severity | R1: AMC Service Type
A2: Month | B2: January | C2: February | D2: March | E2: April | F2: May | G2: June | H2: July | I2: August | J2: September | K2: October | L2: November | M2: December | P2: ACTIVE | Q2: CRITICAL | R2: Comprehensive
A3: Days in Month | B3: 31 | C3: 28 | D3: 31 | E3: 30 | F3: 31 | G3: 30 | H3: 31 | I3: 31 | J3: 30 | K3: 31 | L3: 30 | M3: 31 | P3: EXPIRED | Q3: HIGH | R3: Non-Comprehensive
P4: EXPIRING <=30D | Q4: MEDIUM | R4: Consumable item
A5: Parameter | B5: Value | P5: EXPIRING <=90D | Q5: LOW | R5: Security
A6: Solar Capacity – AKSM (kWp) | B6: 20 | N6: Source: existing workbook denominator | P6: DATE ERROR | Q6: REVIEW | R6: Housekeeping
A7: Solar Capacity – AKHH (kWp) | B7: 50 | N7: Source: existing workbook denominator | P7: INCOMPLETE | Q7: ACTION | R7: AC Service
A8: Audit Date | B8: 46300 | N8: As-of date used for status controls | P8: REVIEW | R8: Internet

Sheet AUDIT CONTROL
A1: FAC-MIS 2026 – AUDIT & REPAIR CONTROL
A2: Control Area | B2: Finding / Repair | C2: Severity | D2: Action Taken | E2: Current Status | F2: Reference
A3: Electrical O43 | B3: Wrong reference F44 in total formula | C3: CRITICAL | D3: Changed to =SUM(C43:N43) | E3: REPAIRED | F3: Electrical Consmp.!O43
A4: Dashboard | B4: Broken #REF! chart and empty executive view | C4: CRITICAL | D4: Rebuilt KPI dashboard with linked metrics | E4: REPAIRED | F4: DASHBOARD
A5: Water KPI | B5: Mixed /24 /30 /31 logic | C5: HIGH | D5: Standardized using Days in Month control row | E5: REPAIRED | F5: Water Consmp.!C5:N41
A6: Water YTD | B6: Column labelled Avg 2026 but contained totals | C6: MEDIUM | D6: Renamed to YTD Total / KPI | E6: REPAIRED | F6: Water Consmp.!O2
A7: AMC dates | B7: Dates mixed as text and serials | C7: HIGH | D7: Converted identifiable dates to real Excel dates | E7: REPAIRED | F7: AMC-LOG!C3:D75
